Workbook
Name EIDIK: βοηθητικό!$AC$1:$AC$3
Name EIDIKOTHTA: _xlfn._TRO_TRAILING(βοηθητικό!$AE$1:$AE$42)
Name EIDOS: [1]data!$F$2:$F$33
Name EPILOGH: βοηθητικό!$V$2:$V$4
Name MHXANIKOS: βοηθητικό!$J$2:$J$354
Name ORARIO: βοηθητικό!$A$2:$A$7
Name SYMVAN: βοηθητικό!$Q$2:$Q$16
Name YPALLHLOS: ΕΠΙΦΥΛΑΚΗ!$E$5:$E$358

Sheet βοηθητικό
A1: ΩΡΑΡΙΟ | C1: ΤΑΕΦΚ Α.Α. - ΤΑΕΦΚ Δ.Α. - ΔΑΕΦΚ-Κ.Ε. | F1: UNIQUE | G1: ΤΟΜΕΑΣ | H1: ΥΠΗΡΕΣΙΑ | I1: ΥΠΗΡΕΣΙΑ ΓΔΑΕΦΚ | J1: ΥΠΑΛΛΗΛΟΙ ΓΔΑΕΦΚ | K1: ΤΗΛΕΦΩΝΟ ΥΠΗΡΕΣΙΑΣ | L1: ΚΙΝΗΤΟ ΤΗΛΕΦΩΝΟ | M1: Email | N1: ΚΛΑΔΟΣ/ΕΙΔΙΚΟΤΗΤΑ | O1: Email | Q1: ΥΠΗΡΕΣΙΑ | T1: ΥΠΗΡΕΣΙΑ | V1: ΕΠΙΛΟΓΗ | Z1: ΔΗΜΟΣ (Π.Ε.) | AA1: ΔΗΜΟΣ | AB1: Π.Ε. | AC1: _ | AE1: {=_xlfn._xlws.SORT(_xlfn.UNIQUE('ΥΠΑΛΛΗΛΟΙ ΓΔΑΕΦΚ'!E2:E447))} -> ΔΕ ΔΙΟΙΚ.-ΛΟΓ.
A2: 07:00 - 15:00 | C2: _ | E2: 1 | F2: _ | G2: _ | H2: _ | I2: _ | J2: _ | K2: _ | L2: _ | M2: _ | N2: _ | O2: _ | P2: _ | Q2: επιλογή από λίστα | S2: _ | T2: _ | X2: =MID(J4,FIND("(",J4)+1,FIND(")",J4)-FIND("(",J4)-1) -> #VALUE! | Z2: _ | AA2: _ | AC2: Διοικητικός | AE2: ΔΕ ΟΔΗΓΩΝ
A3: 07:30 - 15:30 | E3: 2 | H3: Γ.Δ.Α.Ε.Φ.Κ. | I3: Γ.Δ.Α.Ε.Φ.Κ. | J3: _ | P3: 1 | Q3: Γ.Δ.Α.Ε.Φ.Κ. | T3: Γ.Δ.Α.Ε.Φ.Κ. | AC3: Μηχανικός | AE3: ΔΕ ΠΛΗΡΟΦ/ΚΗΣ
A4: 08:00 - 16:00 | C4: ΑΓΑΔΑΚΟΥ ΑΛΚΜΗΝΗ - ΠΕ ΜΗΧΑΝΙΚΩΝ (ΤΑΕΦΚ Α.Α.) | E4: 3 | F4: 1174 | G4: ΓΔΑΕΦΚ | H4: Γ.Δ.Α.Ε.Φ.Κ. | I4: Γ.Δ.Α.Ε.Φ.Κ. | J4: ΔΗΜΟΠΟΥΛΟΥ ΕΥΓΕΝΙΑ | K4: 210 8704705 | L4: 6977628875 | M4: ev.dimopoulou@ggde.gr | N4: ΠΕ ΜΗΧΑΝΙΚΩΝ | O4: edimopoul@gmail.com | P4: 2 | Q4: ΔΑΕΦΚ-ΒΕ | S4: 1 | T4: ΔΑΕΦΚ-ΒΕ | V4: Λ | X4: =MID(J5,FIND("(",J5)+1,FIND(")",J5)-FIND("(",J5)-1) -> #VALUE! | Z4: ΑΒΔΗΡΩΝ (ΞΑΝΘΗΣ) | AA4: ΑΒΔΗΡΩΝ | AB4: ΞΑΝΘΗΣ | AE4: ΠΕ ΑΓΡ.-ΤΟΠ. ΜΗΧ.
A5: 08:30 - 16:30 | C5: ΑΛΕΒΙΖΟΠΟΥΛΟΥ ΟΛΓΑ - ΤΕ ΜΗΧΑΝΙΚΩΝ (ΤΑΕΦΚ Α.Α.) | E5: 4 | F5: 1339 | G5: ΓΔΑΕΦΚ | H5: Γ.Δ.Α.Ε.Φ.Κ. | I5: Γ.Δ.Α.Ε.Φ.Κ. | J5: ΚΑΚΑΒΟΥΛΗ ΣΤΑΥΡΟΥΛΑ | K5: 210 8704705 | L5: 6972221927 | M5: s.kakavouli@ggde.gr | N5: ΠΕ ΠΟΛ. ΜΗΧ. | O5: kakavoulis1@gmail.com | P5: 3 | Q5: ΔΑΕΦΚ-ΔΕ | S5: 2 | T5: ΔΑΕΦΚ-ΔΕ | X5: =MID(J6,FIND("(",J6)+1,FIND(")",J6)-FIND("(",J6)-1) -> #VALUE! | Z5: ΑΓΙΑΣ (ΛΑΡΙΣΑΣ) | AA5: ΑΓΙΑΣ | AB5: ΛΑΡΙΣΑΣ | AE5: ΠΕ ΑΡΧ. ΜΗΧ.
A6: 09:00 - 17:00 | C6: ΒΑΜΒΑΚΙΑΝΟΣ ΑΛΕΞΑΝΔΡΟΣ - ΠΕ ΜΗΧΑΝΙΚΩΝ (ΤΑΕΦΚ Α.Α.) | E6: 5 | F6: 1175 | G6: ΓΔΑΕΦΚ | H6: Γ.Δ.Α.Ε.Φ.Κ. | I6: Γ.Δ.Α.Ε.Φ.Κ. | J6: ΚΑΛΥΒΑ ΕΥΣΤΑΘΙΑ | K6: 210 8704705 | L6: 6974196410 | M6: e.kaliva@ggde.gr | N6: ΠΕ ΜΗΧΑΝΙΚΩΝ | O6: e.kaliva@ggde.gr | P6: 4 | Q6: ΔΑΕΦΚ-ΚΕ | S6: 3 | T6: ΔΑΕΦΚ-ΚΕ | X6: =MID(J7,FIND("(",J7)+1,FIND(")",J7)-FIND("(",J7)-1) -> #VALUE! | Z6: ΑΓΙΟΥ ΒΑΣΙΛΕΙΟΥ (ΡΕΘΥΜΝΟΥ) | AA6: ΑΓΙΟΥ ΒΑΣΙΛΕΙΟΥ | AB6: ΡΕΘΥΜΝΟΥ | AE6: ΠΕ ΓΕΩΛΟΓΩΝ
A7: _ | C7: ΒΟΥΚΕΛΑΤΟΣ ΔΗΜΗΤΡΙΟΣ - ΠΕ ΜΗΧΑΝΙΚΩΝ (ΤΑΕΦΚ Α.Α.) | E7: 6 | F7: 1176 | G7: ΓΔΑΕΦΚ | H7: Γ.Δ.Α.Ε.Φ.Κ. | I7: Γ.Δ.Α.Ε.Φ.Κ. | J7: ΚΛΕΑΝΘΗ ΜΑΡΙΑ | K7: 210 6411902, 2108704710 | L7: 6932969294 | M7: m.kleanthi@ggde.gr | N7: ΠΕ ΜΗΧΑΝΙΚΩΝ | O7: mfkleanthi@yahoo.gr | P7: 5 | Q7: ΔΑΕΦΚ-ΚΕ ΤΜΗΜΑ Α | S7: 4 | T7: ΔΑΕΦΚ-ΚΕ ΤΜΗΜΑ Α | X7: =MID(J8,FIND("(",J8)+1,FIND(")",J8)-FIND("(",J8)-1) -> #VALUE! | Z7: ΑΓΙΟΥ ΝΙΚΟΛΑΟΥ (ΛΑΣΙΘΙΟΥ) | AA7: ΑΓΙΟΥ ΝΙΚΟΛΑΟΥ | AB7: ΛΑΣΙΘΙΟΥ | AE7: ΠΕ ΔΑΣΟΛΟΓΩΝ
C8: ΓΕΩΡΓΟΠΟΥΛΟΥ ΜΑΡΙΑ - ΠΕ ΜΗΧΑΝΙΚΩΝ (ΤΑΕΦΚ Α.Α.) | E8: 7 | F8: 1177 | G8: ΓΔΑΕΦΚ | H8: Γ.Δ.Α.Ε.Φ.Κ. | I8: Γ.Δ.Α.Ε.Φ.Κ. | J8: ΚΥΡΙΑΚΟΥ ΚΩΝΣΤΑΝΤΙΝΟΣ | K8: _ | L8: 6986190056 | M8: k.kyriakou@ggde.gr | N8: ΔΕ ΔΙΟΙΚ.-ΓΡΑΜ. | O8: kkiriakou92@gmail.com, | P8: 6 | Q8: ΔΑΕΦΚ-ΚΕ ΤΜΗΜΑ Β | S8: 5 | T8: ΔΑΕΦΚ-ΚΕ ΤΜΗΜΑ Β | X8: =MID(J9,FIND("(",J9)+1,FIND(")",J9)-FIND("(",J9)-1) -> #VALUE! | Z8: ΑΓΙΩΝ ΑΝΑΡΓΥΡΩΝ - ΚΑΜΑΤΕΡΟΥ (ΔΥΤΙΚΟΥ ΤΟΜΕΑ ΑΘΗΝΩΝ) | AA8: ΑΓΙΩΝ ΑΝΑΡΓΥΡΩΝ - ΚΑΜΑΤΕΡΟΥ | AB8: ΔΥΤΙΚΟΥ ΤΟΜΕΑ ΑΘΗΝΩΝ | AE8: ΠΕ ΔΗΜΟΣ/ΚΩΝ
C9: ΔΗΜΟΠΟΥΛΟΥ ΑΝΝΑ - ΠΕ ΜΗΧΑΝΙΚΩΝ (ΤΑΕΦΚ Α.Α.) | E9: 8 | F9: 1179 | G9: ΓΔΑΕΦΚ | H9: Γ.Δ.Α.Ε.Φ.Κ. | I9: Γ.Δ.Α.Ε.Φ.Κ. | J9: ΠΑΓΙΑΛΑΚΗΣ ΜΙΧΑΗΛ | K9: 28210 29287 | L9: 6932648520 | M9: _ | N9: ΠΕ ΜΗΧΑΝΙΚΩΝ | O9: michalis_pagial@hotmail.com | P9: 7 | Q9: ΔΑΕΦΚ-ΚΕ ΤΜΗΜΑ Γ | S9: 6 | T9: ΔΑΕΦΚ-ΚΕ ΤΜΗΜΑ Γ | Z9: ΑΓΡΑΦΩΝ (ΕΥΡΥΤΑΝΙΑΣ) | AA9: ΑΓΡΑΦΩΝ | AB9: ΕΥΡΥΤΑΝΙΑΣ | AE9: ΠΕ ΔΙΟΙΚ.-ΛΟΓ.
E10: 9 | F10: 1180 | G10: ΓΔΑΕΦΚ | H10: Γ.Δ.Α.Ε.Φ.Κ. | I10: Γ.Δ.Α.Ε.Φ.Κ. | J10: ΣΑΣΣΑΛΟΥ ΜΑΡΙΑ | K10: 2108704742 | L10: 6981049463 | M10: m.sassalou@ggde.gr | N10: ΠΕ ΜΗΧΑΝΙΚΩΝ | O10: marisass64@hotmail.com | P10: 8 | Q10: ΔΑΕΦΚ-ΚΕ ΤΜΗΜΑ Δ | T10: ΔΑΕΦΚ-ΚΕ ΤΜΗΜΑ Δ | AE10: ΠΕ ΔΙΟΙΚ.-ΟΙΚ.
C11: ΔΙΑΜΑΝΤΟΠΟΥΛΟΣ ΓΕΩΡΓΙΟΣ - ΠΕ ΜΗΧΑΝΙΚΩΝ (ΤΑΕΦΚ Α.Α.) | E11: 10 | F11: 1181 | G11: ΓΔΑΕΦΚ | H11: Γ.Δ.Α.Ε.Φ.Κ. | I11: Γ.Δ.Α.Ε.Φ.Κ. | J11: ΣΚΑΝΔΑΛΗ ΑΓΓΕΛΙΚΗ | K11: 2106411902, 2106447566 | L11: 6972713242 | M11: a.skandali@ggde.gr | N11: ΔΕ ΔΙΟΙΚΗΤΙΚΟΥ | O11: skandaliange@gmail.com | P11: 9 | Q11: ΤΑΕΦΚ ΗΡΑΚΛΕΙΟΥ | S11: 7 | T11: ΤΑΕΦΚ ΗΡΑΚΛΕΙΟΥ | Z11: ΑΓΡΙΝΙΟΥ (ΑΙΤΩΛΟΑΚΑΡΝΑΝΙΑΣ) | AA11: ΑΓΡΙΝΙΟΥ | AB11: ΑΙΤΩΛΟΑΚΑΡΝΑΝΙΑΣ | AE11: ΠΕ ΗΛ. ΜΗΧ.
C12: ΚΑΛΦΑΝΤΗΣ ΑΝΑΣΤΑΣΙΟΣ - ΠΕ ΜΗΧΑΝΙΚΩΝ (ΤΑΕΦΚ Α.Α.) | E12: 11 | F12: 1182 | G12: ΓΔΑΕΦΚ | H12: Γ.Δ.Α.Ε.Φ.Κ. | I12: Γ.Δ.Α.Ε.Φ.Κ. | J12: ΤΣΟΥΦΛΙΔΟΥ ΘΕΟΦΑΝΗ | K12: 210 8704735 | L12: 6948545108 | M12: th.tsouflidou@ggde.gr | N12: ΠΕ ΜΗΧΑΝΙΚΩΝ | O12: ftsouflidou@gmail.com | P12: 10 | Q12: ΤΑΕΦΚ ΧΑΝΙΩΝ | S12: 8 | T12: ΤΑΕΦΚ ΧΑΝΙΩΝ | Z12: ΑΘΗΝΑΙΩΝ (ΚΕΝΤΡΙΚΟΥ ΤΟΜΕΑ ΑΘΗΝΩΝ) | AA12: ΑΘΗΝΑΙΩΝ | AB12: ΚΕΝΤΡΙΚΟΥ ΤΟΜΕΑ ΑΘΗΝΩΝ | AE12: ΠΕ ΜΗΧ. ΔΟΜΟΣΤ.
C13: ΚΑΤΩΓΙΑΝΝΑΚΗ ΣΟΦΙΑ - ΠΕ ΜΗΧΑΝΙΚΩΝ (ΤΑΕΦΚ Α.Α.) | E13: 12 | H13: ΔΑΕΦΚ-ΒΕ | I13: ΔΑΕΦΚ-ΒΕ | J13: _ | P13: 11 | Q13: ΤΑΕΦΚ-ΑΑ | S13: 9 | T13: ΤΑΕΦΚ-ΑΑ | Z13: ΑΙΓΙΑΛΕΙΑΣ (ΑΧΑΪΑΣ) | AA13: ΑΙΓΙΑΛΕΙΑΣ | AB13: ΑΧΑΪΑΣ | AE13: ΠΕ ΜΗΧ. ΜΕΤΑΛΛ.
C14: ΚΟΚΚΙΝΟΣ ΗΛΙΑΣ - ΠΕ ΜΗΧΑΝΙΚΩΝ (ΤΑΕΦΚ Α.Α.) | E14: 13 | F14: 1113 | G14: ΒΕ | H14: ΔΑΕΦΚ-ΒΕ | I14: ΔΑΕΦΚ-ΒΕ | J14: ΑΝΑΓΝΩΣΤΟΥ ΑΛΕΞΑΝΔΡΟΣ | K14: 2310 419514 | L14: 6949672608 | M14: a.anagnostou@ggde.gr | N14: ΠΕ ΗΛ. ΜΗΧ. | O14: anagalex1@yahoo.gr | P14: 12 | Q14: ΤΑΕΦΚ-ΔΑ | S14: 10 | T14: ΤΑΕΦΚ-ΔΑ | Z14: ΑΙΓΙΝΑΣ (ΝΗΣΩΝ) | AA14: ΑΙΓΙΝΑΣ | AB14: ΝΗΣΩΝ | AE14: ΠΕ ΜΗΧ. ΜΗΧ.
C15: ΚΟΥΤΣΑΝΙΤΗΣ ΣΤΕΡΓΙΟΣ - ΠΕ ΜΗΧΑΝΙΚΩΝ (ΤΑΕΦΚ Α.Α.) | E15: 14 | F15: 1115 | G15: ΒΕ | H15: ΔΑΕΦΚ-ΒΕ | I15: ΔΑΕΦΚ-ΒΕ | J15: ΑΝΘΟΠΟΥΛΟΥ ΣΟΥΖΑΝΑ | K15: 2310 424027 | L15: 6932853641 | M15: s.anthopoulou@ggde.gr | N15: ΔΕ ΔΙΟΙΚ.-ΛΟΓ. | O15: suzannathess@yahoo.gr, | P15: 14 | S15: 12 | Z15: ΑΛΕΞΑΝΔΡΕΙΑΣ (ΗΜΑΘΙΑΣ) | AA15: ΑΛΕΞΑΝΔΡΕΙΑΣ | AB15: ΗΜΑΘΙΑΣ | AE15: ΠΕ ΜΗΧ. ΟΙΚ. & ΔΙΟΙΚ.
C16: ΚΥΖΙΡΙΔΟΥ ΑΣΗΜΙΝΑ - ΠΕ ΜΗΧΑΝΙΚΩΝ (ΤΑΕΦΚ Α.Α.) | E16: 15 | F16: 1116 | G16: ΒΕ | H16: ΔΑΕΦΚ-ΒΕ | I16: ΔΑΕΦΚ-ΒΕ | J16: ΒΟΓΙΑΤΖΗΣ ΒΑΣΙΛΕΙΟΣ | K16: 2310 419705 | L16: 6981400643 | M16: v.vogiatzis@ggde.gr | N16: ΠΕ ΜΗΧ. ΠΑΡ. | O16: vasilisvog2@gmail.com | P16: 15 | S16: 13 | Z16: ΑΛΕΞΑΝΔΡΟΥΠΟΛΗΣ (ΕΒΡΟΥ) | AA16: ΑΛΕΞΑΝΔΡΟΥΠΟΛΗΣ | AB16: ΕΒΡΟΥ | AE16: ΠΕ ΜΗΧ. ΟΡ. ΠΟΡΩΝ
C17: ΛΕΝΑ ΔΕΣΠΟΙΝΑ - ΠΕ ΜΗΧΑΝΙΚΩΝ (ΤΑΕΦΚ Α.Α.) | E17: 16 | F17: 1117 | G17: ΒΕ | H17: ΔΑΕΦΚ-ΒΕ | I17: ΔΑΕΦΚ-ΒΕ | J17: ΓΕΡΟΚΩΣΤΑ ΚΩΝΣΤΑΝΤΙΑ | K17: 2310 420823 | L17: 6974605685 | M17: k.gerokosta@ggde.gr | N17: ΔΕ ΔΙΟΙΚ.-ΛΟΓ. | O17: kongerok@gmail.com | S17: 14 | Z17: ΑΛΙΑΡΤΟΥ - ΘΕΣΠΙΕΩΝ (ΒΟΙΩΤΙΑΣ) | AA17: ΑΛΙΑΡΤΟΥ - ΘΕΣΠΙΕΩΝ | AB17: ΒΟΙΩΤΙΑΣ | AE17: ΠΕ ΜΗΧ. ΠΑΡ.
C18: ΛΕΥΚΙΜΜΙΑΤΗΣ ΧΑΡΑΛΑΜΠΟΣ - ΠΕ ΜΗΧΑΝΙΚΩΝ (ΤΑΕΦΚ Α.Α.) | E18: 17 | F18: 1118 | G18: ΒΕ | H18: ΔΑΕΦΚ-ΒΕ | I18: ΔΑΕΦΚ-ΒΕ | J18: ΓΕΩΡΓΙΑΔΗΣ ΣΤΑΥΡΟΣ | K18: 2310 414840 | L18: 6944899817 | M18: _ | N18: ΠΕ ΔΙΟΙΚ.-ΟΙΚ. | O18: sgeorgiadis75@gmail.com | S18: 15 | Z18: ΑΛΜΥΡΟΥ (ΜΑΓΝΗΣΙΑΣ) | AA18: ΑΛΜΥΡΟΥ | AB18: ΜΑΓΝΗΣΙΑΣ | AE18: ΠΕ ΜΗΧ. ΠΕΡΙΒΑΛ.
C19: ΛΙΝΤΕΡΗΣ ΔΗΜΗΤΡΙΟΣ - ΠΕ ΜΗΧΑΝΙΚΩΝ (ΤΑΕΦΚ Α.Α.) | E19: 18 | F19: 1119 | G19: ΒΕ | H19: ΔΑΕΦΚ-ΒΕ | I19: ΔΑΕΦΚ-ΒΕ | J19: ΓΙΑΝΝΟΥΛΗ ΒΙΚΤΩΡΙΑ | K19: 2310 428468 | L19: 6987268386 | M19: v.giannouli@ggde.gr | N19: ΠΕ ΠΟΛ. ΜΗΧ. | O19: viktorigd2@gmail.com | S19: 16 | Z19: ΑΛΜΩΠΙΑΣ (ΠΕΛΛΑΣ) | AA19: ΑΛΜΩΠΙΑΣ | AB19: ΠΕΛΛΑΣ | AE19: ΠΕ ΜΗΧ. ΧΩΡ.
C20: ΜΑΚΡΗΣ ΑΥΓΟΥΣΤΙΝΟΣ - ΠΕ ΜΗΧΑΝΙΚΩΝ (ΤΑΕΦΚ Α.Α.) | E20: 19 | F20: 1120 | G20: ΒΕ | H20: ΔΑΕΦΚ-ΒΕ | I20: ΔΑΕΦΚ-ΒΕ | J20: ΓΚΑΦΑΡΙΔΟΥ ΜΑΡΙΑ | K20: 2310 412985 | L20: 6944613389 | M20: m.gkafaridou@ggde.gr | N20: ΠΕ ΤΟΠ. ΜΗΧ. | O20: mgafaridou@gmail.com, | S20: 17 | Z20: ΑΛΜΥΡΟΥ (ΜΑΓΝΗΣΙΑΣ) | AA20: ΑΛΜΥΡΟΥ | AB20: ΜΑΓΝΗΣΙΑΣ | AE20: ΠΕ ΝΟΜΙΚΩΝ
C21: ΜΑΚΡΗΣ ΙΩΑΝΝΗΣ - ΠΕ ΜΗΧΑΝΙΚΩΝ (ΤΑΕΦΚ Α.Α.) | E21: 20 | F21: 1121 | G21: ΒΕ | H21: ΔΑΕΦΚ-ΒΕ | I21: ΔΑΕΦΚ-ΒΕ | J21: ΓΚΟΡΠΑ ΜΑΓΙΟΥΛΑ | K21: 2310 419514 | L21: 6938905960 | M21: m.gkorpa@ggde.gr | N21: ΠΕ ΠΕΡΙΒΑΛ. | O21: magioula@gmail.com | S21: 18 | Z21: ΑΛΜΩΠΙΑΣ (ΠΕΛΛΑΣ) | AA21: ΑΛΜΩΠΙΑΣ | AB21: ΠΕΛΛΑΣ | AE21: ΠΕ ΠΕΡΙΒ/ΝΤΟΣ
C22: ΜΠΑΡΔΗΣ ΓΕΩΡΓΙΟΣ - ΠΕ ΜΗΧΑΝΙΚΩΝ (ΤΑΕΦΚ Α.Α.) | E22: 21 | F22: 1122 | G22: ΒΕ | H22: ΔΑΕΦΚ-ΒΕ | I22: ΔΑΕΦΚ-ΒΕ | J22: ΓΚΟΥΝΤΑΚΟΣ ΓΕΩΡΓΙΟΣ | K22: 2310 419705 | L22: 6942926446 | M22: g.gkountakos@ggde.gr | N22: ΠΕ ΠΟΛ. ΜΗΧ. | O22: giorgosgdk@gmail.com | S22: 19 | Z22: ΑΛΜΥΡΟΥ (ΜΑΓΝΗΣΙΑΣ) | AA22: ΑΛΜΥΡΟΥ | AB22: ΜΑΓΝΗΣΙΑΣ | AE22: ΠΕ ΠΛΗΡΟΦΟΡΙΚΗΣ
C23: ΜΠΙΡΜΠΙΛΗ ΑΝΔΡΙΑΝΝΑ - ΤΕ ΜΗΧΑΝΙΚΩΝ (ΤΑΕΦΚ Α.Α.) | E23: 22 | F23: 1123 | G23: ΒΕ | H23: ΔΑΕΦΚ-ΒΕ | I23: ΔΑΕΦΚ-ΒΕ | J23: ΓΚΟΥΝΤΡΟΜΙΧΟΣ ΙΩΑΝΝΗΣ | K23: 2310 419676 | L23: 6976681245 | M23: i.gkountromichos@ggde.gr | N23: ΠΕ ΠΟΛ. ΜΗΧ. | O23: 6igoudromihos3@gmail.com | S23: 20 | Z23: ΑΛΜΩΠΙΑΣ (ΠΕΛΛΑΣ) | AA23: ΑΛΜΩΠΙΑΣ | AB23: ΠΕΛΛΑΣ | AE23: ΠΕ ΠΟΛ. ΜΗΧ.
C24: ΜΠΟΥΣΟΥΝΗΣ ΙΩΑΝΝΗΣ - ΠΕ ΜΗΧΑΝΙΚΩΝ (ΤΑΕΦΚ Α.Α.) | E24: 23 | F24: 1124 | G24: ΒΕ | H24: ΔΑΕΦΚ-ΒΕ | I24: ΔΑΕΦΚ-ΒΕ | J24: ΓΟΥΛΙΑΣ ΓΕΩΡΓΙΟΣ | K24: 2310 419705 | L24: 6984435383 | M24: g.goulias@ggde.gr | N24: ΠΕ ΠΟΛ. ΜΗΧ. | O24: gouliasg@gmail.com | S24: 22 | Z24: ΑΛΜΩΠΙΑΣ (ΠΕΛΛΑΣ) | AA24: ΑΛΜΩΠΙΑΣ | AB24: ΠΕΛΛΑΣ | AE24: ΠΕ ΧΗΜ. ΜΗΧ.
C25: ΜΠΡΟΝΗΣ ΣΩΤΗΡΙΟΣ - ΠΕ ΜΗΧΑΝΙΚΩΝ (ΤΑΕΦΚ Α.Α.) | E25: 24 | F25: 1125 | G25: ΒΕ | H25: ΔΑΕΦΚ-ΒΕ | I25: ΔΑΕΦΚ-ΒΕ | J25: ΓΟΥΝΑΡΙΔΟΥ ΕΥΧΑΡΙΣ | K25: 2310 416572 | L25: 6974494940 | M25: e.gounaridou@ggde.gr | N25: ΠΕ ΠΟΛ. ΜΗΧ. | O25: efi.gouna@gmail.com | S25: 23 | Z25: ΑΛΜΥΡΟΥ (ΜΑΓΝΗΣΙΑΣ) | AA25: ΑΛΜΥΡΟΥ | AB25: ΜΑΓΝΗΣΙΑΣ | AE25: ΠΕ ΧΗΜΙΚΩΝ
C26: ΠΑΝΤΑΖΗ ΑΛΕΞΑΝΔΡΑ - ΤΕ ΜΗΧΑΝΙΚΩΝ (ΤΑΕΦΚ Α.Α.) | E26: 25 | F26: 1126 | G26: ΒΕ | H26: ΔΑΕΦΚ-ΒΕ | I26: ΔΑΕΦΚ-ΒΕ | J26: ΔΑΛΑΡΗΣ ΑΝΑΡΓΥΡΟΣ | K26: 2310 419793 | L26: 6945581890 | M26: a.dalaris@ggde.gr | N26: ΠΕ ΠΟΛ. ΜΗΧ. | O26: andalaris@gmail.com | S26: 24 | Z26: ΑΛΜΩΠΙΑΣ (ΠΕΛΛΑΣ) | AA26: ΑΛΜΩΠΙΑΣ | AB26: ΠΕΛΛΑΣ | AE26: ΤΕ ΔΙΟΙΚ.-ΛΟΓ.
C27: ΠΑΠΑΔΟΠΟΥΛΟΣ ΕΥΣΤΑΘΙΟΣ - ΠΕ ΜΗΧΑΝΙΚΩΝ (ΤΑΕΦΚ Α.Α.) | E27: 26 | F27: 1127 | G27: ΒΕ | H27: ΔΑΕΦΚ-ΒΕ | I27: ΔΑΕΦΚ-ΒΕ | J27: ΔΑΜΙΑΝΙΔΟΥ ΕΥΘΥΜΙΑ | K27: 2310 417459 | L27: 6979228710 | M27: e.damianidou@ggde.gr | N27: ΠΕ ΑΡΧ. ΜΗΧ. | O27: efidamia@yahoo.com | S27: 25 | Z27: ΑΛΜΥΡΟΥ (ΜΑΓΝΗΣΙΑΣ) | AA27: ΑΛΜΥΡΟΥ | AB27: ΜΑΓΝΗΣΙΑΣ | AE27: ΤΕ ΔΟΜ. ΕΡΓΩΝ
C28: ΠΑΠΠΗ ΦΩΤΕΙΝΗ - ΠΕ ΜΗΧΑΝΙΚΩΝ (ΤΑΕΦΚ Α.Α.) | E28: 27 | F28: 1128 | G28: ΒΕ | H28: ΔΑΕΦΚ-ΒΕ | I28: ΔΑΕΦΚ-ΒΕ | J28: ΔΑΣΚΑΛΗ ΒΑΣΙΛΙΚΗ | K28: 2310 419705 | L28: 6946431686 | M28: v.daskali@ggde.gr | N28: ΠΕ ΠΟΛ. ΜΗΧ. | O28: vdask1003@gmail.com | S28: 26 | Z28: ΑΛΜΩΠΙΑΣ (ΠΕΛΛΑΣ) | AA28: ΑΛΜΩΠΙΑΣ | AB28: ΠΕΛΛΑΣ | AE28: ΤΕ ΗΛ. ΜΗΧ.
... C35: _ | E35: 34 | F35: 1138 | G35: ΒΕ | H35: ΔΑΕΦΚ-ΒΕ | I35: ΔΑΕΦΚ-ΒΕ | J35: ΚΑΡΑΜΠΑΣΗΣ ΧΡΗΣΤΟΣ | K35: 2310 414840 | L35: 6947449447 | M35: c.karampasis@ggde.gr | N35: ΠΕ ΠΟΛ. ΜΗΧ. | O35: rythmosk@otenet.gr | S35: 33 | Z35: ΑΛΜΥΡΟΥ (ΜΑΓΝΗΣΙΑΣ) | AA35: ΑΛΜΥΡΟΥ | AB35: ΜΑΓΝΗΣΙΑΣ | AE35: ΤΕ ΤΟΠΟΓΡ. ΜΗΧ.
C36: ΑΓΓΕΛΗ ΚΩΝΣΤΑΝΤΙΝΑ - ΠΕ ΜΗΧΑΝΙΚΩΝ (ΤΑΕΦΚ Δ.Α.) | E36: 35 | F36: 1139 | G36: ΒΕ | H36: ΔΑΕΦΚ-ΒΕ | I36: ΔΑΕΦΚ-ΒΕ | J36: ΚΑΡΥΔΑ ΑΓΑΠΗ | K36: 2310 416834 | L36: 6944508818 | M36: a.karyda@ggde.gr | N36: ΠΕ ΤΟΠ. ΜΗΧ. | O36: agapikaryda@gmail.com | S36: 34 | Z36: ΑΛΜΩΠΙΑΣ (ΠΕΛΛΑΣ) | AA36: ΑΛΜΩΠΙΑΣ | AB36: ΠΕΛΛΑΣ
C37: ΑΘΑΝΑΣΙΟΥ ΠΑΝΑΓΙΩΤΗΣ - ΠΕ ΜΗΧΑΝΙΚΩΝ (ΤΑΕΦΚ Δ.Α.) | E37: 36 | F37: 1140 | G37: ΒΕ | H37: ΔΑΕΦΚ-ΒΕ | I37: ΔΑΕΦΚ-ΒΕ | J37: ΚΕΛΕΚΤΣΟΓΛΟΥ ΣΤΑΥΡΟΥΛΑ | K37: 2310 423979 | L37: 6977827750 | M37: s.kelektsoglou@ggde.gr | N37: ΤΕ ΔΙΟΙΚ.-ΛΟΓ. | O37: skelek75@yahoo.gr | S37: 35 | Z37: ΑΛΜΥΡΟΥ (ΜΑΓΝΗΣΙΑΣ) | AA37: ΑΛΜΥΡΟΥ | AB37: ΜΑΓΝΗΣΙΑΣ
C38: ΑΤΑΜΕΓΚΟΣ ΓΡΗΓΟΡΙΟΣ - ΤΕ ΜΗΧΑΝΙΚΩΝ (ΤΑΕΦΚ Δ.Α.) | E38: 37 | F38: 1142 | G38: ΒΕ | H38: ΔΑΕΦΚ-ΒΕ | I38: ΔΑΕΦΚ-ΒΕ | J38: ΚΟΚΚΙΝΙΔΟΥ ΠΕΛΑΓΙΑ | K38: 2310 419705 | L38: 6978486629 | M38: p.kokkinidou@ggde.gr | N38: ΠΕ ΠΟΛ. ΜΗΧ. | O38: pelagi14@yahoo.gr | S38: 36 | Z38: ΑΛΜΩΠΙΑΣ (ΠΕΛΛΑΣ) | AA38: ΑΛΜΩΠΙΑΣ | AB38: ΠΕΛΛΑΣ
C39: ΑΦΡΙΚΑΝΟΣ ΑΛΕΞΗΣ - ΠΕ ΜΗΧΑΝΙΚΩΝ (ΤΑΕΦΚ Δ.Α.) | E39: 38 | F39: 1144 | G39: ΒΕ | H39: ΔΑΕΦΚ-ΒΕ | I39: ΔΑΕΦΚ-ΒΕ | J39: ΚΡΙΝΟΥ ΕΥΤΥΧΙΑ | K39: 2310 801853 | L39: 6936783135 | M39: e.krinou@ggde.gr | N39: ΔΕ ΠΡΟΣ. Η/Υ | O39: eftihiakrinou@yahoo.gr | S39: 37 | Z39: ΑΛΜΥΡΟΥ (ΜΑΓΝΗΣΙΑΣ) | AA39: ΑΛΜΥΡΟΥ | AB39: ΜΑΓΝΗΣΙΑΣ
C40: ΒΑΣΙΛΑΚΟΠΟΥΛΟΣ ΑΘΑΝΑΣΙΟΣ - ΠΕ ΜΗΧΑΝΙΚΩΝ (ΤΑΕΦΚ Δ.Α.) | E40: 39 | F40: 1145 | G40: ΒΕ | H40: ΔΑΕΦΚ-ΒΕ | I40: ΔΑΕΦΚ-ΒΕ | J40: ΛΕΜΟΝΗ ΕΛΕΝΗ | K40: 2310 801853 | L40: 6945415670 | M40: e.lemoni@ggde.gr | N40: ΠΕ ΓΕΩΤΕΧΝΙΚΩΝ | O40: lemonielen@gmail.com | S40: 38 | Z40: ΑΛΜΩΠΙΑΣ (ΠΕΛΛΑΣ) | AA40: ΑΛΜΩΠΙΑΣ | AB40: ΠΕΛΛΑΣ
C41: ΒΕΝΕΤΣΑΝΟΣ ΕΠΑΜΕΙΝΩΝΔΑΣ - ΠΕ ΜΗΧΑΝΙΚΩΝ (ΤΑΕΦΚ Δ.Α.) | E41: 40 | F41: 1146 | G41: ΒΕ | H41: ΔΑΕΦΚ-ΒΕ | I41: ΔΑΕΦΚ-ΒΕ | J41: ΜΑΝΩΛΗΣ ΑΝΤΩΝΗΣ | K41: 2310 421674 | L41: 6944744680 | M41: a.manolis@ggde.gr | N41: ΠΕ ΤΟΠ. ΜΗΧ. | O41: antonismanolis@hotmail.com | S41: 39 | Z41: ΑΛΜΥΡΟΥ (ΜΑΓΝΗΣΙΑΣ) | AA41: ΑΛΜΥΡΟΥ | AB41: ΜΑΓΝΗΣΙΑΣ
C42: ΓΕΩΡΓΙΟΥ ΚΩΝΣΤΑΝΤΙΝΟΣ - ΤΕ ΜΗΧΑΝΙΚΩΝ (ΤΑΕΦΚ Δ.Α.) | E42: 41 | F42: 1147 | G42: ΒΕ | H42: ΔΑΕΦΚ-ΒΕ | I42: ΔΑΕΦΚ-ΒΕ | J42: ΜΑΤΘΑΙΟΥ ΓΕΩΡΓΙΟΣ | K42: 2310 419705 | L42: 6907366486 | M42: g.matthaiou@ggde.gr | N42: ΤΕ ΓΕΩΠΛΗΡ. | O42: geormatth@gmail.com | S42: 40 | Z42: ΑΛΜΩΠΙΑΣ (ΠΕΛΛΑΣ) | AA42: ΑΛΜΩΠΙΑΣ | AB42: ΠΕΛΛΑΣ
C43: ΘΕΛΕΡΙΤΗΣ ΗΛΙΑΣ - ΠΕ ΜΗΧΑΝΙΚΩΝ (ΤΑΕΦΚ Δ.Α.) | E43: 42 | F43: 1149 | G43: ΒΕ | H43: ΔΑΕΦΚ-ΒΕ | I43: ΔΑΕΦΚ-ΒΕ | J43: ΜΠΑΚΑ ΜΑΡΙΑ | K43: 2310 428468 | L43: 6947932494 | M43: m.baka@ggde.gr | N43: ΠΕ ΤΟΠ. ΜΗΧ. | O43: mariadbaka@gmail.com | S43: 41 | Z43: ΑΛΜΥΡΟΥ (ΜΑΓΝΗΣΙΑΣ) | AA43: ΑΛΜΥΡΟΥ | AB43: ΜΑΓΝΗΣΙΑΣ
E44: 43 | F44: 1150 | G44: ΒΕ | H44: ΔΑΕΦΚ-ΒΕ | I44: ΔΑΕΦΚ-ΒΕ | J44: ΜΠΑΚΑΛΟΥΔΗ ΘΕΟΔΩΡΑ | K44: 2310 411840 | L44: 6936772633 | M44: _ | N44: ΠΕ ΔΙΟΙΚ.-ΟΙΚ. | O44: mpakaloudit@gmail.com
C45: ΙΩΑΝΝΙΔΗΣ ΔΗΜΟΣΘΕΝΗΣ - ΠΕ ΜΗΧΑΝΙΚΩΝ (ΤΑΕΦΚ Δ.Α.) | E45: 44 | F45: 1151 | G45: ΒΕ | H45: ΔΑΕΦΚ-ΒΕ | I45: ΔΑΕΦΚ-ΒΕ | J45: ΜΠΑΛΑΣΑΣ ΑΝΤΩΝΙΟΣ | K45: 2310 423641 | L45: 6947830538 | M45: a.balasas@ggde.gr | N45: ΠΕ ΔΙΟΙΚ.-ΟΙΚ. | O45: anton.balasas.kif.thes@gmail.com | S45: 42 | Z45: ΑΛΜΩΠΙΑΣ (ΠΕΛΛΑΣ) | AA45: ΑΛΜΩΠΙΑΣ | AB45: ΠΕΛΛΑΣ
C46: ΚΑΡΑΚΩΣΤΑΣ ΠΑΝΑΓΙΩΤΗΣ - ΠΕ ΜΗΧΑΝΙΚΩΝ (ΤΑΕΦΚ Δ.Α.) | E46: 45 | F46: 1152 | G46: ΒΕ | H46: ΔΑΕΦΚ-ΒΕ | I46: ΔΑΕΦΚ-ΒΕ | J46: ΜΠΙΣΜΠΑ ΑΦΡΟΔΙΤΗ | K46: 2310 419705 | L46: 6945879061 | M46: a.bismpa@ggde.gr | N46: ΠΕ ΠΟΛ. ΜΗΧ. | O46: afroditibisba@gmail.com | S46: 44 | Z46: ΑΛΜΩΠΙΑΣ (ΠΕΛΛΑΣ) | AA46: ΑΛΜΩΠΙΑΣ | AB46: ΠΕΛΛΑΣ
...

Sheet ΜΗΧΑΝΙΚΟΙ
B1: Γ.Δ.Α.Ε.Φ.Κ. - ΚΑΤΑΛΟΓΟΣ ΜΗΧΑΝΙΚΩΝ
A2: αα | B2: ΤΟΜΕΑΣ | C2: Α.Μ. | D2: ΟΝΟΜΑΤΕΠΩΝΥΜΟ | E2: Μηχανικοί | F2: Α.Φ.Μ. | G2: ΚΙΝΗΤΟ ΤΗΛΕΦΩΝΟ | H2: ΚΛΑΔΟΣ/ΕΙΔΙΚΟΤΗΤΑ | I2: Μηχανικός /Διοικητικός | J2: υπηρεσιακό Email | K2: προσωπικό Email
A3: =--SUBTOTAL(3,$B$2:B2) -> 1 | B3: ΑΑ | C3: 14328 | D3: ΑΝΑΓΝΩΣΤΟΥ ΜΑΡΙΑ ΙΩΑΝΝΑ | E3: ΑΝΑΓΝΩΣΤΟΥ ΜΑΡΙΑ ΙΩΑΝΝΑ - ΠΕ ΜΗΧ. ΟΙΚ. & ΔΙΟΙΚ. (ΤΑΕΦΚ-ΑΑ) | F3: 151036800 | G3: 6980996968 | H3: ΠΕ ΜΗΧ. ΟΙΚ. & ΔΙΟΙΚ. | I3: Μηχανικός | J3: managnostou@civilprotection.gr | K3: marianna.anagnostou@gmail.com | L3: =_xlfn.XLOOKUP(C3,'ΥΠΑΛΛΗΛΟΙ ΓΔΑΕΦΚ'!#REF!,'ΥΠΑΛΛΗΛΟΙ ΓΔΑΕΦΚ'!#REF!,"_") -> #REF!
A4: =--SUBTOTAL(3,$B$2:B3) -> 2 | B4: ΑΑ | C4: 12426 | D4: ΑΠΟΣΤΟΛΙΔΟΥ ΙΩΑΝΝΑ | E4: ΑΠΟΣΤΟΛΙΔΟΥ ΙΩΑΝΝΑ - ΠΕ ΠΟΛ. ΜΗΧ. (ΤΑΕΦΚ-ΑΑ) | F4: 044407577 | G4: 6978300669 | H4: ΠΕ ΠΟΛ. ΜΗΧ. | I4: Μηχανικός | J4: iapostolidou@civilprotection.gr | K4: joan.apostolidou@gmail.com, ioannaapostolidoy@hotmail.com | L4: =_xlfn.XLOOKUP(C4,'ΥΠΑΛΛΗΛΟΙ ΓΔΑΕΦΚ'!#REF!,'ΥΠΑΛΛΗΛΟΙ ΓΔΑΕΦΚ'!#REF!,"_") -> #REF!
A5: =--SUBTOTAL(3,$B$2:B4) -> 3 | B5: ΑΑ | C5: 14229 | D5: ΒΑΜΒΑΚΙΑΝΟΣ ΑΛΕΞΑΝΔΡΟΣ | E5: ΒΑΜΒΑΚΙΑΝΟΣ ΑΛΕΞΑΝΔΡΟΣ - ΠΕ ΠΟΛ. ΜΗΧ. (ΤΑΕΦΚ-ΑΑ) | F5: 147180480 | G5: 6970320059 | H5: ΠΕ ΠΟΛ. ΜΗΧ. | I5: Μηχανικός | J5: avamvakianos@civilprotection.gr | K5: alex_vnos@hotmail.com | L5: =_xlfn.XLOOKUP(C5,'ΥΠΑΛΛΗΛΟΙ ΓΔΑΕΦΚ'!#REF!,'ΥΠΑΛΛΗΛΟΙ ΓΔΑΕΦΚ'!#REF!,"_") -> #REF!
A6: =--SUBTOTAL(3,$B$2:B5) -> 4 | B6: ΑΑ | C6: 14224 | D6: ΒΟΥΚΕΛΑΤΟΣ ΔΗΜΗΤΡΙΟΣ | E6: ΒΟΥΚΕΛΑΤΟΣ ΔΗΜΗΤΡΙΟΣ - ΠΕ ΜΗΧΑΝΙΚΩΝ (ΤΑΕΦΚ-ΑΑ) | F6: 049749197 | G6: 6932544495 | H6: ΠΕ ΜΗΧΑΝΙΚΩΝ | I6: Μηχανικός | J6: dvoukelatos@civilprotection.gr | K6: _ | L6: =_xlfn.XLOOKUP(C6,'ΥΠΑΛΛΗΛΟΙ ΓΔΑΕΦΚ'!#REF!,'ΥΠΑΛΛΗΛΟΙ ΓΔΑΕΦΚ'!#REF!,"_") -> #REF!
A7: =--SUBTOTAL(3,$B$2:B6) -> 5 | B7: ΑΑ | C7: 12274 | D7: ΓΑΒΡΙΛΙΑΔΗ ΑΦΡΟΔΙΤΗ | E7: ΓΑΒΡΙΛΙΑΔΗ ΑΦΡΟΔΙΤΗ - ΤΕ ΠΟΛ. ΜΗΧ. (ΤΑΕΦΚ-ΑΑ) | F7: 076058054 | G7: 6947007553 | H7: ΤΕ ΠΟΛ. ΜΗΧ. | I7: Μηχανικός | J7: agavriliadi@civilprotection.gr | K7: _ | L7: =_xlfn.XLOOKUP(C7,'ΥΠΑΛΛΗΛΟΙ ΓΔΑΕΦΚ'!#REF!,'ΥΠΑΛΛΗΛΟΙ ΓΔΑΕΦΚ'!#REF!,"_") -> #REF!
A8: =--SUBTOTAL(3,$B$2:B7) -> 6 | B8: ΑΑ | C8: 14168 | D8: ΓΕΩΡΓΟΠΟΥΛΟΥ ΜΑΡΙΑ | E8: ΓΕΩΡΓΟΠΟΥΛΟΥ ΜΑΡΙΑ - ΠΕ ΠΟΛ. ΜΗΧ. (ΤΑΕΦΚ-ΑΑ) | F8: 073455287 | G8: 6972820547 | H8: ΠΕ ΠΟΛ. ΜΗΧ. | I8: Μηχανικός | J8: mgeorgopoulou@civilprotection.gr | K8: georgopmara@yahoo.gr | L8: =_xlfn.XLOOKUP(C8,'ΥΠΑΛΛΗΛΟΙ ΓΔΑΕΦΚ'!#REF!,'ΥΠΑΛΛΗΛΟΙ ΓΔΑΕΦΚ'!#REF!,"_") -> #REF!
A9: =--SUBTOTAL(3,$B$2:B8) -> 7 | B9: ΑΑ | C9: 14250 | D9: ΔΙΑΜΑΝΤΟΠΟΥΛΟΣ ΓΕΩΡΓΙΟΣ | E9: ΔΙΑΜΑΝΤΟΠΟΥΛΟΣ ΓΕΩΡΓΙΟΣ - ΠΕ ΑΡΧ. ΜΗΧ. (ΤΑΕΦΚ-ΑΑ) | F9: 147171970 | G9: 6939405094 | H9: ΠΕ ΑΡΧ. ΜΗΧ. | I9: Μηχανικός | J9: gdiamantopoulos@civilprotection.gr | K9: gdiamantopoulos17@gmail.com | L9: =_xlfn.XLOOKUP(C9,'ΥΠΑΛΛΗΛΟΙ ΓΔΑΕΦΚ'!#REF!,'ΥΠΑΛΛΗΛΟΙ ΓΔΑΕΦΚ'!#REF!,"_") -> #REF!
A10: =--SUBTOTAL(3,$B$2:B9) -> 8 | B10: ΑΑ | C10: 14194 | D10: ΚΟΚΚΙΝΟΣ ΗΛΙΑΣ | E10: ΚΟΚΚΙΝΟΣ ΗΛΙΑΣ - ΠΕ ΠΟΛ. ΜΗΧ. (ΤΑΕΦΚ-ΑΑ) | F10: 142738116 | G10: 6984576537 | H10: ΠΕ ΠΟΛ. ΜΗΧ. | I10: Μηχανικός | J10: ikokkinos@civilprotection.gr | K10: iliasbkokkinos@gmail.com | L10: =_xlfn.XLOOKUP(C10,'ΥΠΑΛΛΗΛΟΙ ΓΔΑΕΦΚ'!#REF!,'ΥΠΑΛΛΗΛΟΙ ΓΔΑΕΦΚ'!#REF!,"_") -> #REF!
A11: =--SUBTOTAL(3,$B$2:B10) -> 9 | B11: ΑΑ | C11: 14230 | D11: ΚΟΥΡΗ ΝΙΚΟΛΕΤΑ | E11: ΚΟΥΡΗ ΝΙΚΟΛΕΤΑ - ΠΕ ΑΡΧ. ΜΗΧ. (ΤΑΕΦΚ-ΑΑ) | F11: 124661936 | G11: 6932637784 | H11: ΠΕ ΑΡΧ. ΜΗΧ. | I11: Μηχανικός | J11: nkouri@civilprotection.gr | K11: nikoletakouri@gmail.com | L11: =_xlfn.XLOOKUP(C11,'ΥΠΑΛΛΗΛΟΙ ΓΔΑΕΦΚ'!#REF!,'ΥΠΑΛΛΗΛΟΙ ΓΔΑΕΦΚ'!#REF!,"_") -> #REF!
A12: =--SUBTOTAL(3,$B$2:B11) -> 10 | B12: ΑΑ | C12: 14231 | D12: ΛΕΝΑ ΔΕΣΠΟΙΝΑ | E12: ΛΕΝΑ ΔΕΣΠΟΙΝΑ - ΠΕ ΠΟΛ. ΜΗΧ. (ΤΑΕΦΚ-ΑΑ) | F12: 137601500 | G12: 6977421366 | H12: ΠΕ ΠΟΛ. ΜΗΧ. | I12: Μηχανικός | J12: dlena@civilprotection.gr | K12: despinle@hotmail.com | L12: =_xlfn.XLOOKUP(C12,'ΥΠΑΛΛΗΛΟΙ ΓΔΑΕΦΚ'!#REF!,'ΥΠΑΛΛΗΛΟΙ ΓΔΑΕΦΚ'!#REF!,"_") -> #REF!
A13: =--SUBTOTAL(3,$B$2:B12) -> 11 | B13: ΑΑ | C13: 14169 | D13: ΛΙΝΤΕΡΗΣ ΔΗΜΗΤΡΙΟΣ | E13: ΛΙΝΤΕΡΗΣ ΔΗΜΗΤΡΙΟΣ - ΠΕ ΠΟΛ. ΜΗΧ. (ΤΑΕΦΚ-ΑΑ) | F13: 045943810 | G13: 6977303667 | H13: ΠΕ ΠΟΛ. ΜΗΧ. | I13: Μηχανικός | J13: dlinteris@civilprotection.gr | K13: dimlinteris@yahoo.gr | L13: =_xlfn.XLOOKUP(C13,'ΥΠΑΛΛΗΛΟΙ ΓΔΑΕΦΚ'!#REF!,'ΥΠΑΛΛΗΛΟΙ ΓΔΑΕΦΚ'!#REF!,"_") -> #REF!
A14: =--SUBTOTAL(3,$B$2:B13) -> 12 | B14: ΑΑ | C14: 14209 | D14: ΜΑΚΡΗΣ ΑΥΓΟΥΣΤΙΝΟΣ | E14: ΜΑΚΡΗΣ ΑΥΓΟΥΣΤΙΝΟΣ - ΠΕ ΠΟΛ. ΜΗΧ. (ΤΑΕΦΚ-ΑΑ) | F14: 078166374 | G14: 6942496492 | H14: ΠΕ ΠΟΛ. ΜΗΧ. | I14: Μηχανικός | J14: amakris@civilprotection.gr | K14: augmakris@yahoo.com | L14: =_xlfn.XLOOKUP(C14,'ΥΠΑΛΛΗΛΟΙ ΓΔΑΕΦΚ'!#REF!,'ΥΠΑΛΛΗΛΟΙ ΓΔΑΕΦΚ'!#REF!,"_") -> #REF!
... A172: =--SUBTOTAL(3,$B$2:B171) -> 170 | B172: ΚΕ-Β | C172: 13835 | D172: ΜΑΥΡΟΓΕΝΗΣ ΑΝΤΩΝΙΟΣ | E172: ΜΑΥΡΟΓΕΝΗΣ ΑΝΤΩΝΙΟΣ - ΠΕ ΠΟΛ. ΜΗΧ. (ΔΑΕΦΚ-ΚΕ ΤΜΗΜΑ Β) | F172: 046698010 | G172: 6972150340 | H172: ΠΕ ΠΟΛ. ΜΗΧ. | I172: Μηχανικός | J172: amavrogenis@civilprotection.gr | K172: lentasdv@gmail.com | L172: =_xlfn.XLOOKUP(C172,'ΥΠΑΛΛΗΛΟΙ ΓΔΑΕΦΚ'!#REF!,'ΥΠΑΛΛΗΛΟΙ ΓΔΑΕΦΚ'!#REF!,"_") -> #REF!
A173: =--SUBTOTAL(3,$B$2:B172) -> 171 | B173: ΚΕ-Β | C173: 12227 | D173: ΠΑΝΑΓΙΩΤΙΔΗΣ ΜΙΧΑΗΛ | E173: ΠΑΝΑΓΙΩΤΙΔΗΣ ΜΙΧΑΗΛ - ΠΕ ΠΟΛ. ΜΗΧ. (ΟΑΣΠ) | F173: 052113201 | G173: 6985565922 | H173: ΠΕ ΠΟΛ. ΜΗΧ. | J173: mpanagiotidis@civilprotection.gr | L173: =_xlfn.XLOOKUP(C173,'ΥΠΑΛΛΗΛΟΙ ΓΔΑΕΦΚ'!#REF!,'ΥΠΑΛΛΗΛΟΙ ΓΔΑΕΦΚ'!#REF!,"_") -> #REF!
A174: =--SUBTOTAL(3,$B$2:B173) -> 172 | B174: ΚΕ-Β | C174: 20535 | D174: ΠΑΠΑΔΟΠΟΥΛΟΣ ΑΝΑΣΤΑΣΙΟΣ | E174: ΠΑΠΑΔΟΠΟΥΛΟΣ ΑΝΑΣΤΑΣΙΟΣ - ΠΕ ΑΡΧ. ΜΗΧ. (ΔΑΕΦΚ-ΚΕ ΤΜΗΜΑ Β) | F174: 044143997 | G174: 6944688337 | H174: ΠΕ ΑΡΧ. ΜΗΧ. | I174: Μηχανικός | J174: apapadopoulos@civilprotection.gr | K174: tasos.x.papadopoulos@gmail.com | L174: =_xlfn.XLOOKUP(C174,'ΥΠΑΛΛΗΛΟΙ ΓΔΑΕΦΚ'!#REF!,'ΥΠΑΛΛΗΛΟΙ ΓΔΑΕΦΚ'!#REF!,"_") -> #REF!
A175: =--SUBTOTAL(3,$B$2:B174) -> 173 | B175: ΚΕ-Γ | C175: 900263 | D175: ΑΣΒΕΣΤΑΣ ΙΩΑΝΝΗΣ | E175: ΑΣΒΕΣΤΑΣ ΙΩΑΝΝΗΣ - ΤΕ ΗΛ. ΜΗΧ. (ΔΑΕΦΚ-ΚΕ ΤΜΗΜΑ Γ) | F175: 054031829 | G175: 6980736334 | H175: ΤΕ ΗΛ. ΜΗΧ. | I175: Μηχανικός | J175: iasvestas@civilprotection.gr | K175: gasvest@gmail.com | L175: =_xlfn.XLOOKUP(C175,'ΥΠΑΛΛΗΛΟΙ ΓΔΑΕΦΚ'!#REF!,'ΥΠΑΛΛΗΛΟΙ ΓΔΑΕΦΚ'!#REF!,"_") -> #REF!
A176: =--SUBTOTAL(3,$B$2:B175) -> 174 | B176: ΚΕ-Γ | C176: 12107 | D176: ΒΛΑΧΟΓΙΑΝΝΗΣ ΚΩΝΣΤΑΝΤΙΝΟΣ | E176: ΒΛΑΧΟΓΙΑΝΝΗΣ ΚΩΝΣΤΑΝΤΙΝΟΣ - ΠΕ ΜΗΧ. ΜΗΧ. (ΔΑΕΦΚ-ΚΕ ΤΜΗΜΑ Γ) | F176: 051735090 | G176: 6976657104 | H176: ΠΕ ΜΗΧ. ΜΗΧ. | I176: Μηχανικός | J176: kvlachogiannis@civilprotection.gr | K176: _ | L176: =_xlfn.XLOOKUP(C176,'ΥΠΑΛΛΗΛΟΙ ΓΔΑΕΦΚ'!#REF!,'ΥΠΑΛΛΗΛΟΙ ΓΔΑΕΦΚ'!#REF!,"_") -> #REF!
A177: =--SUBTOTAL(3,$B$2:B176) -> 175 | B177: ΚΕ-Γ | C177: 20101 | D177: ΓΙΑΡΓΚΙΤΖΗ ΑΝΝΑ | E177: ΓΙΑΡΓΚΙΤΖΗ ΑΝΝΑ - ΠΕ ΑΡΧ. ΜΗΧ. (ΔΑΕΦΚ-ΚΕ ΤΜΗΜΑ Γ) | F177: 043813858 | G177: 6978894699 | H177: ΠΕ ΑΡΧ. ΜΗΧ. | I177: Μηχανικός | J177: agiargkitzi@civilprotection.gr | K177: agiatzi@gmail.com | L177: =_xlfn.XLOOKUP(C177,'ΥΠΑΛΛΗΛΟΙ ΓΔΑΕΦΚ'!#REF!,'ΥΠΑΛΛΗΛΟΙ ΓΔΑΕΦΚ'!#REF!,"_") -> #REF!
A178: =--SUBTOTAL(3,$B$2:B177) -> 176 | B178: ΚΕ-Γ | C178: 4819 | D178: ΔΕΔΕΣ ΗΡΑΚΛΗΣ | E178: ΔΕΔΕΣ ΗΡΑΚΛΗΣ - ΤΕ ΜΗΧ. ΜΗΧ. (ΔΑΕΦΚ-ΚΕ ΤΜΗΜΑ Γ) | F178: 034828063 | G178: 6978335362 | H178: ΤΕ ΜΗΧ. ΜΗΧ. | I178: Μηχανικός | J178: idedes@civilprotection.gr | K178: _ | L178: =_xlfn.XLOOKUP(C178,'ΥΠΑΛΛΗΛΟΙ ΓΔΑΕΦΚ'!#REF!,'ΥΠΑΛΛΗΛΟΙ ΓΔΑΕΦΚ'!#REF!,"_") -> #REF!
A179: =--SUBTOTAL(3,$B$2:B178) -> 177 | B179: ΚΕ-Γ | C179: 14331 | D179: ΔΙΠΛΑ ΑΝΤΩΝΙΑ | E179: ΔΙΠΛΑ ΑΝΤΩΝΙΑ - ΠΕ ΠΟΛ. ΜΗΧ. (ΔΑΕΦΚ-ΚΕ ΤΜΗΜΑ Γ) | F179: 134512650 | G179: 6989602050 | H179: ΠΕ ΠΟΛ. ΜΗΧ. | I179: Μηχανικός | J179: adipla@civilprotection.gr | K179: dipla_ant@hotmail.com | L179: =_xlfn.XLOOKUP(C179,'ΥΠΑΛΛΗΛΟΙ ΓΔΑΕΦΚ'!#REF!,'ΥΠΑΛΛΗΛΟΙ ΓΔΑΕΦΚ'!#REF!,"_") -> #REF!
A180: =--SUBTOTAL(3,$B$2:B179) -> 178 | B180: ΚΕ-Γ | C180: 12431 | D180: ΚΕΒΕΡΗΣ ΜΙΧΑΗΛ | E180: ΚΕΒΕΡΗΣ ΜΙΧΑΗΛ - ΠΕ ΠΟΛ. ΜΗΧ. (ΔΑΕΦΚ-ΚΕ ΤΜΗΜΑ Γ) | F180: 045639509 | G180: _ | H180: ΠΕ ΠΟΛ. ΜΗΧ. | I180: Μηχανικός | J180: mkeveris@civilprotection.gr | K180: _ | L180: =_xlfn.XLOOKUP(C180,'ΥΠΑΛΛΗΛΟΙ ΓΔΑΕΦΚ'!#REF!,'ΥΠΑΛΛΗΛΟΙ ΓΔΑΕΦΚ'!#REF!,"_") -> #REF!
A181: =--SUBTOTAL(3,$B$2:B180) -> 179 | B181: ΚΕ-Γ | C181: 5802 | D181: ΜΗΤΡΟΠΟΥΛΟΣ ΔΗΜΗΤΡΙΟΣ | E181: ΜΗΤΡΟΠΟΥΛΟΣ ΔΗΜΗΤΡΙΟΣ - ΠΕ ΗΛ. ΜΗΧ. (ΔΑΕΦΚ-ΚΕ ΤΜΗΜΑ Γ) | F181: 025094759 | G181: 6934973849 | H181: ΠΕ ΗΛ. ΜΗΧ. | I181: Μηχανικός | J181: dmitropoulos@civilprotection.gr | K181: _ | L181: =_xlfn.XLOOKUP(C181,'ΥΠΑΛΛΗΛΟΙ ΓΔΑΕΦΚ'!#REF!,'ΥΠΑΛΛΗΛΟΙ ΓΔΑΕΦΚ'!#REF!,"_") -> #REF!
A182: =--SUBTOTAL(3,$B$2:B181) -> 180 | B182: ΚΕ-Γ | C182: 12470 | D182: ΜΠΕΡΤΣΙΑΣ ΜΙΛΤΙΑΔΗΣ | E182: ΜΠΕΡΤΣΙΑΣ ΜΙΛΤΙΑΔΗΣ - ΤΕ ΠΟΛ. ΜΗΧ. (ΔΑΕΦΚ-ΚΕ ΤΜΗΜΑ Γ) | F182: 051181250 | G182: 6974321817 | H182: ΤΕ ΠΟΛ. ΜΗΧ. | I182: Μηχανικός | J182: mmpertsias@civilprotection.gr | K182: miltos.ber@gmail.com | L182: =_xlfn.XLOOKUP(C182,'ΥΠΑΛΛΗΛΟΙ ΓΔΑΕΦΚ'!#REF!,'ΥΠΑΛΛΗΛΟΙ ΓΔΑΕΦΚ'!#REF!,"_") -> #REF!
A183: =--SUBTOTAL(3,$B$2:B182) -> 181 | B183: ΚΕ-Γ | C183: 45644 | D183: ΞΕΝΟΥ ΣΤΑΜΑΤΙΝΑ | E183: ΞΕΝΟΥ ΣΤΑΜΑΤΙΝΑ - ΠΕ ΑΡΧ. ΜΗΧ. (ΔΑΕΦΚ-ΚΕ ΤΜΗΜΑ Γ) | F183: 064305183 | G183: 6972234942 | H183: ΠΕ ΑΡΧ. ΜΗΧ. | I183: Μηχανικός | J183: sxenou@civilprotection.gr | K183: _ | L183: =_xlfn.XLOOKUP(C183,'ΥΠΑΛΛΗΛΟΙ ΓΔΑΕΦΚ'!#REF!,'ΥΠΑΛΛΗΛΟΙ ΓΔΑΕΦΚ'!#REF!,"_") -> #REF!
A184: =--SUBTOTAL(3,$B$2:B183) -> 182 | B184: ΚΕ-Γ | C184: 12460 | D184: ΠΑΝΑΓΙΩΤΟΥΛΙΑ ΒΑΣΙΛΙΚΗ | E184: ΠΑΝΑΓΙΩΤΟΥΛΙΑ ΒΑΣΙΛΙΚΗ - ΠΕ ΑΡΧ. ΜΗΧ. (ΔΑΕΦΚ-ΚΕ ΤΜΗΜΑ Γ) | F184: 046396787 | G184: 6977293089 | H184: ΠΕ ΑΡΧ. ΜΗΧ. | I184: Μηχανικός | J184: vpanagiotoulia@civilprotection.gr | K184: _ | L184: =_xlfn.XLOOKUP(C184,'ΥΠΑΛΛΗΛΟΙ ΓΔΑΕΦΚ'!#REF!,'ΥΠΑΛΛΗΛΟΙ ΓΔΑΕΦΚ'!#REF!,"_") -> #REF!
A185: =--SUBTOTAL(3,$B$2:B184) -> 183 | B185: ΚΕ-Γ | C185: 5059 | D185: ΤΖΑΝΑΚΗΣ ΙΩΑΝΝΗΣ | E185: ΤΖΑΝΑΚΗΣ ΙΩΑΝΝΗΣ - ΤΕ ΤΟΠΟΓΡ. ΜΗΧ. (ΟΑΣΠ) | F185: 033521725 | G185: 6944345730 | H185: ΤΕ ΤΟΠΟΓΡ. ΜΗΧ. | J185: itzanakis@civilprotection.gr | L185: =_xlfn.XLOOKUP(C185,'ΥΠΑΛΛΗΛΟΙ ΓΔΑΕΦΚ'!#REF!,'ΥΠΑΛΛΗΛΟΙ ΓΔΑΕΦΚ'!#REF!,"_") -> #REF!
A186: =--SUBTOTAL(3,$B$2:B185) -> 184 | B186: ΚΕ-Γ | C186: 102917 | D186: ΤΣΟΥΜΗΣ ΙΩΑΝΝΗΣ | E186: ΤΣΟΥΜΗΣ ΙΩΑΝΝΗΣ - ΤΕ ΗΛ. ΜΗΧ. (ΔΑΕΦΚ-ΚΕ ΤΜΗΜΑ Γ) | F186: 031000868 | G186: 6972309803 | H186: ΤΕ ΗΛ. ΜΗΧ. | I186: Μηχανικός | J186: itsoumis@civilprotection.gr | K186: _ | L186: =_xlfn.XLOOKUP(C186,'ΥΠΑΛΛΗΛΟΙ ΓΔΑΕΦΚ'!#REF!,'ΥΠΑΛΛΗΛΟΙ ΓΔΑΕΦΚ'!#REF!,"_") -> #REF!
A187: =--SUBTOTAL(3,$B$2:B186) -> 185 | B187: ΚΕ-Δ | C187: 14438 | D187: ΑΓΓΕΛΗΣ ΙΩΑΝΝΗΣ | E187: ΑΓΓΕΛΗΣ ΙΩΑΝΝΗΣ - ΠΕ ΠΟΛ. ΜΗΧ. (ΔΑΕΦΚ-ΚΕ ΤΜΗΜΑ Δ) | F187: 129541130 | G187: 6970117758 | H187: ΠΕ ΠΟΛ. ΜΗΧ. | I187: Μηχανικός | J187: iangelis@civilprotection.gr | K187: ioannes.angelis@gmail.com | L187: =_xlfn.XLOOKUP(C187,'ΥΠΑΛΛΗΛΟΙ ΓΔΑΕΦΚ'!#REF!,'ΥΠΑΛΛΗΛΟΙ ΓΔΑΕΦΚ'!#REF!,"_") -> #REF!
A188: =--SUBTOTAL(3,$B$2:B187) -> 186 | B188: ΚΕ-Δ | C188: 12530 | D188: ΑΓΙΑΝΟΓΛΟΥ ΒΑΣΙΛΕΙΟΣ | E188: ΑΓΙΑΝΟΓΛΟΥ ΒΑΣΙΛΕΙΟΣ - ΠΕ ΑΡΧ. ΜΗΧ. (ΔΑΕΦΚ-ΚΕ ΤΜΗΜΑ Δ) | F188: 043410897 | G188: 6974929090 | H188: ΠΕ ΑΡΧ. ΜΗΧ. | I188: Μηχανικός | J188: vagianoglou@civilprotection.gr | K188: v.agianoglou@gmail.com | L188: =_xlfn.XLOOKUP(C188,'ΥΠΑΛΛΗΛΟΙ ΓΔΑΕΦΚ'!#REF!,'ΥΠΑΛΛΗΛΟΙ ΓΔΑΕΦΚ'!#REF!,"_") -> #REF!
A189: =--SUBTOTAL(3,$B$2:B188) -> 187 | B189: ΚΕ-Δ | C189: 14461 | D189: ΑΗΔΟΝΗ ΕΛΕΝΗ | E189: ΑΗΔΟΝΗ ΕΛΕΝΗ - ΠΕ ΠΟΛ. ΜΗΧ. (ΔΑΕΦΚ-ΚΕ ΤΜΗΜΑ Δ) | F189: 133400980 | G189: 6934671271 | H189: ΠΕ ΠΟΛ. ΜΗΧ. | I189: Μηχανικός | J189: e.aidoni@civilprotection.gr | K189: helenaid@gmail.com | L189: =_xlfn.XLOOKUP(C189,'ΥΠΑΛΛΗΛΟΙ ΓΔΑΕΦΚ'!#REF!,'ΥΠΑΛΛΗΛΟΙ ΓΔΑΕΦΚ'!#REF!,"_") -> #REF!
A190: =--SUBTOTAL(3,$B$2:B189) -> 188 | B190: ΚΕ-Δ | C190: 14201 | D190: ΑΛΕΒΙΖΟΠΟΥΛΟΥ ΟΛΓΑ | E190: ΑΛΕΒΙΖΟΠΟΥΛΟΥ ΟΛΓΑ - ΤΕ ΜΗΧΑΝΙΚΩΝ (ΔΑΕΦΚ-ΚΕ ΤΜΗΜΑ Δ) | F190: 154885734 | G190: 6972406536 | H190: ΤΕ ΜΗΧΑΝΙΚΩΝ | I190: Μηχανικός | J190: oalevizopoulou@civilprotection.gr | K190: taefkaa.alevizopoulou@gmail.com | L190: =_xlfn.XLOOKUP(C190,'ΥΠΑΛΛΗΛΟΙ ΓΔΑΕΦΚ'!#REF!,'ΥΠΑΛΛΗΛΟΙ ΓΔΑΕΦΚ'!#REF!,"_") -> #REF!
A191: =--SUBTOTAL(3,$B$2:B190) -> 189 | B191: ΚΕ-Δ | C191: 14329 | D191: ΒΑΙΛΑΚΗΣ ΔΗΜΗΤΡΙΟΣ | E191: ΒΑΙΛΑΚΗΣ ΔΗΜΗΤΡΙΟΣ - ΠΕ ΠΟΛ. ΜΗΧ. (ΔΑΕΦΚ-ΚΕ ΤΜΗΜΑ Δ) | F191: 073906576 | G191: 6932393388 | H191: ΠΕ ΠΟΛ. ΜΗΧ. | I191: Μηχανικός | J191: dvailakis@civilprotection.gr | K191: dimitris.vailakis@gmail.com | L191: =_xlfn.XLOOKUP(C191,'ΥΠΑΛΛΗΛΟΙ ΓΔΑΕΦΚ'!#REF!,'ΥΠΑΛΛΗΛΟΙ ΓΔΑΕΦΚ'!#REF!,"_") -> #REF!
A192: =--SUBTOTAL(3,$B$2:B191) -> 190 | B192: ΚΕ-Δ | C192: 900299 | D192: ΒΕΣΤΑΡΧΗΣ ΝΙΚΟΛΑΟΣ | E192: ΒΕΣΤΑΡΧΗΣ ΝΙΚΟΛΑΟΣ - ΠΕ ΜΗΧΑΝΙΚΩΝ (ΔΑΕΦΚ-ΚΕ ΤΜΗΜΑ Δ) | F192: 106684339 | G192: 6931583774 | H192: ΠΕ ΜΗΧΑΝΙΚΩΝ | I192: Μηχανικός | J192: nvestarchis@civilprotection.gr | K192: nvestarchis@gmail.com | L192: =_xlfn.XLOOKUP(C192,'ΥΠΑΛΛΗΛΟΙ ΓΔΑΕΦΚ'!#REF!,'ΥΠΑΛΛΗΛΟΙ ΓΔΑΕΦΚ'!#REF!,"_") -> #REF!
A193: =--SUBTOTAL(3,$B$2:B192) -> 191 | B193: ΚΕ-Δ | C193: 12647 | D193: ΓΕΜΕΛΙΑΡΗ ΕΙΡΗΝΗ | E193: ΓΕΜΕΛΙΑΡΗ ΕΙΡΗΝΗ - ΠΕ ΠΟΛ. ΜΗΧ. (ΔΑΕΦΚ-ΚΕ ΤΜΗΜΑ Δ) | F193: 056724365 | G193: 6972084481 | H193: ΠΕ ΠΟΛ. ΜΗΧ. | I193: Μηχανικός | J193: egemeliari@civilprotection.gr | K193: irene.gemeliari@gmail.com | L193: =_xlfn.XLOOKUP(C193,'ΥΠΑΛΛΗΛΟΙ ΓΔΑΕΦΚ'!#REF!,'ΥΠΑΛΛΗΛΟΙ ΓΔΑΕΦΚ'!#REF!,"_") -> #REF!
A194: =--SUBTOTAL(3,$B$2:B193) -> 192 | B194: ΚΕ-Δ | C194: 14174 | D194: ΓΕΩΡΓΙΟΥ ΚΩΝΣΤΑΝΤΙΝΟΣ | E194: ΓΕΩΡΓΙΟΥ ΚΩΝΣΤΑΝΤΙΝΟΣ - ΤΕ ΜΗΧΑΝΙΚΩΝ (ΔΑΕΦΚ-ΚΕ) | F194: 067980030 | G194: 6977995010 | H194: ΤΕ ΜΗΧΑΝΙΚΩΝ | I194: Μηχανικός | J194: kgeorgiou@civilprotection.gr | K194: kgeorgiou2310@gmail.com | L194: =_xlfn.XLOOKUP(C194,'ΥΠΑΛΛΗΛΟΙ ΓΔΑΕΦΚ'!#REF!,'ΥΠΑΛΛΗΛΟΙ ΓΔΑΕΦΚ'!#REF!,"_") -> #REF!
A195: =--SUBTOTAL(3,$B$2:B194) -> 193 | B195: ΚΕ-Δ | C195: 14378 | D195: ΓΙΑΒΡΟΥΤΑ ΛΑΜΠΡΙΝΗ | E195: ΓΙΑΒΡΟΥΤΑ ΛΑΜΠΡΙΝΗ - ΤΕ ΜΗΧΑΝΙΚΩΝ (ΔΑΕΦΚ-ΚΕ ΤΜΗΜΑ Δ) | F195: 158182687 | G195: 6948491981 | H195: ΤΕ ΜΗΧΑΝΙΚΩΝ | I195: Μηχανικός | J195: lgiavrouta@civilprotection.gr | K195: linagiavrouta@hotmail.com | L195: =_xlfn.XLOOKUP(C195,'ΥΠΑΛΛΗΛΟΙ ΓΔΑΕΦΚ'!#REF!,'ΥΠΑΛΛΗΛΟΙ ΓΔΑΕΦΚ'!#REF!,"_") -> #REF!
A196: =--SUBTOTAL(3,$B$2:B195) -> 194 | B196: ΚΕ-Δ | C196: 12108 | D196: ΓΙΑΝΝΕΛΟΣ ΙΩΑΝΝΗΣ | E196: ΓΙΑΝΝΕΛΟΣ ΙΩΑΝΝΗΣ - ΠΕ ΤΟΠ. ΜΗΧ. (ΔΑΕΦΚ-ΚΕ ΤΜΗΜΑ Δ) | F196: 109400088 | G196: 6944377718 | H196: ΠΕ ΤΟΠ. ΜΗΧ. | I196: Μηχανικός | J196: igiannelos@civilprotection.gr | K196: iugiann@yahoo.gr | L196: =_xlfn.XLOOKUP(C196,'ΥΠΑΛΛΗΛΟΙ ΓΔΑΕΦΚ'!#REF!,'ΥΠΑΛΛΗΛΟΙ ΓΔΑΕΦΚ'!#REF!,"_") -> #REF!
A197: =--SUBTOTAL(3,$B$2:B196) -> 195 | B197: ΚΕ-Δ | C197: 14330 | D197: ΓΙΑΝΝΟΥΛΑΣ ΠΑΝΑΓΙΩΤΗΣ | E197: ΓΙΑΝΝΟΥΛΑΣ ΠΑΝΑΓΙΩΤΗΣ - ΠΕ ΑΡΧ. ΜΗΧ. (ΔΑΕΦΚ-ΚΕ ΤΜΗΜΑ Δ) | F197: 045203505 | G197: 6980042920 | H197: ΠΕ ΑΡΧ. ΜΗΧ. | I197: Μηχανικός | J197: pgiannoulas@civilprotection.gr | K197: panos.giannoulas@gmail.com | L197: =_xlfn.XLOOKUP(C197,'ΥΠΑΛΛΗΛΟΙ ΓΔΑΕΦΚ'!#REF!,'ΥΠΑΛΛΗΛΟΙ ΓΔΑΕΦΚ'!#REF!,"_") -> #REF!
...

Sheet ΥΠΑΛΛΗΛΟΙ ΓΔΑΕΦΚ
A1: surname | B1: name | C1: fathername | D1: afm | E1: klados | F1: attribute | G1: workaf | H1: monada
A2: ΑΛΕΞΟΠΟΥΛΟΥ | B2: ΝΙΚΟΛΙΤΣΑ | C2: ΔΗΜΗΤΡΙΟΣ | D2: 053487141 | E2: ΠΕ ΔΙΟΙΚ.-ΛΟΓ. | F2: Διοικητικός | G2: ΙΔΑΧ | H2: ΤΑΕΦΚ-ΑΑ
A3: ΑΝΑΓΝΩΣΤΟΥ | B3: ΜΑΡΙΑ ΙΩΑΝΝΑ | C3: ΧΡΗΣΤΟΣ | D3: 151036800 | E3: ΠΕ ΜΗΧ. ΟΙΚ. & ΔΙΟΙΚ. | F3: Διοικητικός | G3: ΙΔΟΧ | H3: ΤΑΕΦΚ-ΑΑ
A4: ΑΠΟΣΤΟΛΙΔΟΥ | B4: ΙΩΑΝΝΑ | C4: ΑΝΔΡΕΑΣ | D4: 044407577 | E4: ΠΕ ΠΟΛ. ΜΗΧ. | F4: Μηχανικός | G4: ΙΔΑΧ | H4: ΤΑΕΦΚ-ΑΑ
A5: ΒΑΜΒΑΚΙΑΝΟΣ | B5: ΑΛΕΞΑΝΔΡΟΣ | C5: ΠΑΝΤΕΛΕΗΜΩΝ | D5: 147180480 | E5: ΠΕ ΠΟΛ. ΜΗΧ. | F5: Μηχανικός | G5: ΙΔΟΧ | H5: ΤΑΕΦΚ-ΑΑ
A6: ΓΑΒΡΙΛΙΑΔΗ | B6: ΑΦΡΟΔΙΤΗ | C6: ΠΑΝΑΓΙΩΤΗΣ | D6: 076058054 | E6: ΤΕ ΠΟΛ. ΜΗΧ. | F6: Μηχανικός | G6: ΙΔΑΧ | H6: ΤΑΕΦΚ-ΑΑ
A7: ΓΕΩΡΓΟΠΟΥΛΟΥ | B7: ΜΑΡΙΑ | C7: ΣΠΥΡΙΔΩΝ | D7: 073455287 | E7: ΠΕ ΠΟΛ. ΜΗΧ. | F7: Μηχανικός | G7: ΙΔΟΧ | H7: ΤΑΕΦΚ-ΑΑ
A8: ΔΙΑΜΑΝΤΟΠΟΥΛΟΣ | B8: ΓΕΩΡΓΙΟΣ | C8: ΚΩΝΣΤΑΝΤΙΝΟΣ | D8: 147171970 | E8: ΠΕ ΑΡΧ. ΜΗΧ. | F8: Μηχανικός | G8: ΙΔΟΧ | H8: ΤΑΕΦΚ-ΑΑ
A9: ΖΑΡΑΓΚΑ | B9: ΚΑΛΛΙΟΠΗ | C9: ΘΕΜΙΣΤΟΚΛΗΣ | D9: 023695268 | E9: ΔΕ ΔΙΟΙΚ.-ΛΟΓ. | F9: Διοικητικός | G9: ΙΔΟΧ | H9: ΤΑΕΦΚ-ΑΑ
A10: ΚΟΚΚΙΝΟΣ | B10: ΗΛΙΑΣ | C10: ΒΑΣΙΛΕΙΟΣ | D10: 142738116 | E10: ΠΕ ΠΟΛ. ΜΗΧ. | F10: Μηχανικός | G10: ΙΔΟΧ | H10: ΤΑΕΦΚ-ΑΑ
A11: ΚΟΥΡΗ | B11: ΝΙΚΟΛΕΤΑ | C11: ΓΕΩΡΓΙΟΣ | D11: 124661936 | E11: ΠΕ ΑΡΧ. ΜΗΧ. | F11: Μηχανικός | G11: ΙΔΟΧ | H11: ΤΑΕΦΚ-ΑΑ
A12: ΛΑΖΑΡΟΥ | B12: ΧΑΡΑΛΑΜΠΟΣ | C12: ΑΘΑΝΑΣΙΟΣ | D12: 149952916 | E12: ΔΕ ΔΙΟΙΚ.-ΛΟΓ. | F12: Διοικητικός | G12: ΙΔΟΧ | H12: ΤΑΕΦΚ-ΑΑ
... A84: ΤΣΙΑΠΑΡΙΚΟΥ | B84: ΕΛΙΣΣΑΒΕΤ | C84: ΑΘΑΝΑΣΙΟΣ | D84: 070490837 | E84: ΠΕ ΔΙΟΙΚ.-ΟΙΚ. | F84: Διοικητικός | G84: ΙΔΟΧ | H84: ΔΑΕΦΚ-ΑΚ
A85: ΤΣΟΜΠΟΥ | B85: ΕΥΑΓΓΕΛΙΑ | C85: ΒΑΣΙΛΕΙΟΣ | D85: 156275731 | E85: ΤΕ ΔΙΟΙΚ.-ΛΟΓ. | F85: Διοικητικός | G85: ΙΔΟΧ | H85: ΔΑΕΦΚ-ΑΚ
A86: ΤΣΟΥΦΛΙΔΟΥ | B86: ΑΙΚΑΤΕΡΙΝΗ | C86: ΧΑΡΑΛΑΜΠΟΣ | D86: 124446044 | E86: ΤΕ ΠΟΛ. ΜΗΧ. | F86: Μηχανικός | G86: ΙΔΟΧ | H86: ΔΑΕΦΚ-ΑΚ
A87: ΧΑΝΟΥΜΗΣ | B87: ΔΗΜΗΤΡΙΟΣ | C87: ΚΩΝΣΤΑΝΤΙΝΟΣ | D87: 158034076 | E87: ΤΕ ΠΟΛ. ΜΗΧ. | F87: Μηχανικός | G87: ΙΔΟΧ | H87: ΔΑΕΦΚ-ΑΚ
A88: ΧΑΡΑΛΑΜΠΑΚΗ | B88: ΓΕΩΡΓΙΑ | C88: ΚΩΝΣΤΑΝΤΙΝΟΣ | D88: 147008840 | E88: ΠΕ ΑΡΧ. ΜΗΧ. | F88: Μηχανικός | G88: ΙΔΟΧ | H88: ΔΑΕΦΚ-ΑΚ
A89: ΑΝΑΓΝΩΣΤΟΥ | B89: ΑΛΕΞΑΝΔΡΟΣ | C89: ΑΘΑΝΑΣΙΟΣ | D89: 072492691 | E89: ΠΕ ΗΛ. ΜΗΧ. | F89: Μηχανικός | G89: ΙΔΑΧ | H89: ΔΑΕΦΚ-ΒΕ
A90: ΑΝΘΟΠΟΥΛΟΥ | B90: ΣΟΥΖΑΝΑ | C90: ΚΟΣΜΑΣ | D90: 038117084 | E90: ΔΕ ΔΙΟΙΚ.-ΛΟΓ. | F90: Διοικητικός | G90: ΜΟΝΙΜΟΣ | H90: ΔΑΕΦΚ-ΒΕ
A91: ΒΟΓΙΑΤΖΗΣ | B91: ΒΑΣΙΛΕΙΟΣ | C91: ΔΗΜΗΤΡΙΟΣ | D91: 116711711 | E91: ΠΕ ΜΗΧ. ΠΑΡ. | F91: Μηχανικός | G91: ΙΔΟΧ | H91: ΔΑΕΦΚ-ΒΕ
A92: ΓΕΡΟΚΩΣΤΑ | B92: ΚΩΝΣΤΑΝΤΙΑ | C92: ΠΕΤΡΟΣ | D92: 116709531 | E92: ΔΕ ΔΙΟΙΚ.-ΛΟΓ. | F92: Διοικητικός | G92: ΙΔΑΧ | H92: ΔΑΕΦΚ-ΒΕ
A93: ΓΕΩΡΓΙΑΔΗΣ | B93: ΣΤΑΥΡΟΣ | C93: ΝΙΚΗΦΟΡΟΣ | D93: 126771070 | E93: ΠΕ ΔΙΟΙΚ.-ΟΙΚ. | F93: Διοικητικός | G93: ΙΔΟΧ | H93: ΔΑΕΦΚ-ΒΕ
A94: ΓΙΑΝΝΟΥΛΗ | B94: ΒΙΚΤΩΡΙΑ | C94: ΔΗΜΗΤΡΙΟΣ | D94: 159530499 | E94: ΠΕ ΠΟΛ. ΜΗΧ. | F94: Μηχανικός | G94: ΙΔΟΧ | H94: ΔΑΕΦΚ-ΒΕ
A95: ΓΚΑΦΑΡΙΔΟΥ | B95: ΜΑΡΙΑ | C95: ΔΗΜΗΤΡΙΟΣ | D95: 046016408 | E95: ΠΕ ΑΓΡ.-ΤΟΠ. ΜΗΧ. | F95: Μηχανικός | G95: ΙΔΑΧ | H95: ΔΑΕΦΚ-ΒΕ
A96: ΓΚΟΡΠΑ | B96: ΜΑΓΙΟΥΛΑ | C96: ΠΑΝΑΓΙΩΤΗΣ | D96: 062758281 | E96: ΠΕ ΠΕΡΙΒ/ΝΤΟΣ | F96: Διοικητικός | G96: ΙΔΑΧ | H96: ΔΑΕΦΚ-ΒΕ
A97: ΓΚΟΥΝΤΑΚΟΣ | B97: ΓΕΩΡΓΙΟΣ | C97: ΧΡΗΣΤΟΣ | D97: 133884226 | E97: ΠΕ ΠΟΛ. ΜΗΧ. | F97: Μηχανικός | G97: ΙΔΟΧ | H97: ΔΑΕΦΚ-ΒΕ
A98: ΓΚΟΥΝΤΡΟΜΙΧΟΣ | B98: ΙΩΑΝΝΗΣ | C98: ΑΘΑΝΑΣΙΟΣ | D98: 043451241 | E98: ΠΕ ΠΟΛ. ΜΗΧ. | F98: Μηχανικός | G98: ΙΔΑΧ | H98: ΔΑΕΦΚ-ΒΕ
A99: ΓΟΥΛΙΑΣ | B99: ΓΕΩΡΓΙΟΣ | C99: ΑΛΕΞΑΝΔΡΟΣ | D99: 050626176 | E99: ΠΕ ΠΟΛ. ΜΗΧ. | F99: Μηχανικός | G99: ΙΔΟΧ | H99: ΔΑΕΦΚ-ΒΕ
A100: ΔΑΛΑΡΗΣ | B100: ΑΝΑΡΓΥΡΟΣ | C100: ΗΛΙΑΣ | D100: 046190331 | E100: ΠΕ ΠΟΛ. ΜΗΧ. | F100: Μηχανικός | G100: ΙΔΑΧ | H100: ΔΑΕΦΚ-ΒΕ
... A117: ΜΙΣΑΗΛΙΔΟΥ | B117: ΔΕΣΠΟΙΝΑ | C117: ΓΕΩΡΓΙΟΣ | D117: 133510093 | E117: ΤΕ ΠΟΛ. ΜΗΧ. | F117: Μηχανικός | G117: ΙΔΟΧ | H117: ΔΑΕΦΚ-ΒΕ
A118: ΜΠΑΚΑ | B118: ΜΑΡΙΑ | D118: 101278023 | E118: ΠΕ ΑΓΡ.-ΤΟΠ. ΜΗΧ. | F118: Μηχανικός | G118: ΜΟΝΙΜΟΣ | H118: ΔΑΕΦΚ-ΒΕ
A119: ΜΠΑΚΑΛΟΥΔΗ | B119: ΘΕΟΔΩΡΑ | C119: ΑΘΑΝΑΣΙΟΣ | D119: 037424338 | E119: ΠΕ ΔΙΟΙΚ.-ΟΙΚ. | F119: Διοικητικός | G119: ΙΔΟΧ | H119: ΔΑΕΦΚ-ΒΕ
A120: ΜΠΑΛΑΣΑΣ | B120: ΑΝΤΩΝΙΟΣ | C120: ΔΗΜΗΤΡΙΟΣ | D120: 059701068 | E120: ΠΕ ΔΙΟΙΚ.-ΟΙΚ. | F120: Διοικητικός | G120: ΙΔΑΧ | H120: ΔΑΕΦΚ-ΒΕ
A121: ΜΠΙΣΜΠΑ | B121: ΑΦΡΟΔΙΤΗ | C121: ΧΡΗΣΤΟΣ | D121: 146603145 | E121: ΠΕ ΠΟΛ. ΜΗΧ. | F121: Μηχανικός | G121: ΙΔΟΧ | H121: ΔΑΕΦΚ-ΒΕ
A122: ΠΑΙΔΑΡΑΚΗ | B122: ΓΡΑΜΜΑΤΟΥΛΑ | C122: ΣΤΑΥΡΟΣ | D122: 044549346 | E122: ΤΕ ΠΟΛ. ΜΗΧ. | F122: Μηχανικός | G122: ΙΔΟΧ | H122: ΔΑΕΦΚ-ΒΕ
A123: ΠΑΛΑΙΟΧΩΡΙΝΟΥ | B123: ΑΝΑΣΤΑΣΙΑ | C123: ΦΩΤΙΟΣ | D123: 140806110 | E123: ΠΕ ΠΟΛ. ΜΗΧ. | F123: Μηχανικός | G123: ΙΔΟΧ | H123: ΔΑΕΦΚ-ΒΕ
A124: ΠΑΠΑΒΑΣΙΛΕΙΟΥ | B124: ΟΛΓΑ | C124: ΧΡΗΣΤΟΣ | D124: 047083130 | E124: ΠΕ ΠΟΛ. ΜΗΧ. | F124: Μηχανικός | G124: ΙΔΑΧ | H124: ΔΑΕΦΚ-ΒΕ
A125: ΠΑΠΑΔΟΠΟΥΛΟΣ | B125: ΚΛΗΜΗΣ | C125: ΚΟΣΜΑΣ | D125: 036193915 | E125: ΠΕ ΠΟΛ. ΜΗΧ. | F125: Μηχανικός | G125: ΙΔΑΧ | H125: ΔΑΕΦΚ-ΒΕ
A126: ΠΕΤΑΛΩΤΗΣ | B126: ΔΗΜΗΤΡΙΟΣ | C126: ΠΑΣΧΑΛΗΣ | D126: 113799262 | E126: ΤΕ ΠΟΛ. ΜΗΧ. | F126: Μηχανικός | G126: ΙΔΟΧ | H126: ΔΑΕΦΚ-ΒΕ
A127: ΠΕΧΛΙΒΑΝΟΥ | B127: ΑΙΚΑΤΕΡΙΝΗ | C127: ΔΗΜΗΤΡΙΟΣ | D127: 049001369 | E127: ΠΕ ΠΟΛ. ΜΗΧ. | F127: Μηχανικός | G127: ΜΟΝΙΜΟΣ | H127: ΔΑΕΦΚ-ΒΕ
...

Sheet Sheet1
B2: α/α | C2: ΟΝΟΜΑΤΕΠΩΝΥΜΟ | D2: ΤΗΛΕΦΩΝΟ | E2: υπηρεσιακό Email | F2: ΣΧΕΣΗ ΕΡΓΑΣΙΑΣ
B3: 1 | C3: ΖΟΥΓΡΗΣ ΔΗΜΗΤΡΙΟΣ | D3: 6984118511 | E3: dzougris@civilprotection.gr | F3: ΙΔΟΧ
B4: 2 | C4: ΚΑΡΑΒΙΑΣ ΔΗΜΗΤΡΙΟΣ | D4: 6972386367 | E4: dkaravias@civilprotection.gr | F4: ΙΔΟΧ
B5: 3 | C5: ΚΑΤΩΓΙΑΝΝΑΚΗ ΣΟΦΙΑ | D5: 6978307239 | E5: skatogiannaki@civilprotection.gr | F5: ΙΔΟΧ
B6: 4 | C6: ΠΑΡΔΑΛΗ ΑΝΑΣΤΑΣΙΑ | D6: 6983652275 | E6: apardali@civilprotection.gr | F6: ΙΔΟΧ
B7: 5 | C7: ΣΠΑΝΟΥΔΗ ΜΑΡΙΑ | D7: 6948254859 | E7: mspanoudi@civilprotection.gr | F7: ΙΔΑΧ
B8: 1 | C8: ΑΗΔΟΝΗ ΕΛΕΝΗ | D8: 6934671271 | E8: e.aidoni@civilprotection.gr | F8: ΙΔΟΧ
B9: 2 | C9: ΚΑΡΑΓΙΑΝΝΗΣ ΦΩΤΙΟΣ | D9: 6932438715 | E9: fkaragiannis@civilprotection.gr | F9: ΙΔΑΧ
B10: 3 | C10: ΚΑΤΣΙΩΛΗ ΜΑΡΙΑ | D10: 6937084222 | E10: mkatsioli@civilprotection.gr | F10: ΙΔΑΧ
B11: 4 | C11: ΝΤΑΛΑΠΕΡΑΣ ΓΕΩΡΓΙΟΣ | D11: 6981800426 | E11: gntalaperas@civilprotection.gr | F11: ΙΔΟΧ
B12: 5 | C12: ΣΑΡΛΑΣ ΜΑΡΙΝΟΣ | D12: 6973806827 | E12: msarlas@civilprotection.gr | F12: ΙΔΟΧ

Sheet ΑΠΟΧΩΡΗΣΑΝΤΕΣ
C1: Γ.Δ.Α.Ε.Φ.Κ. - ΚΑΤΑΛΟΓΟΣ ΥΠΑΛΛΗΛΩΝ ΠΟΥ ΔΕΝ ΕΊΝΑΙ ΣΤΗΝ ΥΠΗΡΕΣΙΑ
A2: α/α | B2: UNIQUE | C2: ΤΟΜΕΑΣ | D2: Α.Μ. | E2: ΕΠΩΝΥΜΟ | F2: ΟΝΟΜΑ | G2: ΠΑΤΡΩΝΥΜΟ | H2: ΟΝΟΜΑΤΕΠΩΝΥΜΟ | I2: μηχανικοι | J2: Α.Φ.Μ. | K2: ΕΣΩΤΕΡΙΚΟ ΤΗΛΕΦΩΝΟ | L2: ΤΗΛΕΦΩΝΟ ΥΠΗΡΕΣΙΑΣ | M2: ΤΗΛΕΦΩΝΟ ΟΙΚΙΑΣ | N2: ΚΙΝΗΤΟ ΤΗΛΕΦΩΝΟ | O2: ΚΛΑΔΟΣ/ΕΙΔΙΚΟΤΗΤΑ | P2: [Μ]/[Δ] | Q2: Μηχανικός /Διοικητικός | R2: ΣΧΕΣΗ ΕΡΓΑΣΙΑΣ | S2: υπηρεσιακό Email | T2: προσωπικό Email | U2: ΥΠΗΡΕΣΙΑ/ΤΜΗΜΑ | V2: ΔΙΑΘΕΣΗ ΚΑΙ ΠΑΡΑΛΛΗΛΑ ΚΑΘΗΚΟΝΤΑ ΣΕ ΑΛΛΗ ΥΠΗΡΕΣΙΑ | W2: ΥΠΗΡΕΤΕΙ ΤΩΡΑ | X2: ΚΛΙΜΑΚΙΟ | Y2: ΗΜΕΡΟΜΗΝΙΑ, ΤΕΛΕΥΤΑΙΑΣ, ΑΛΛΑΓΗΣ | Z2: ΑΠΟΦΑΣΕΙΣ, ΚΛΙΜΑΚΙΩΝ | AA2: ΗΜΕΡΟΜΗΝΙΑ, ΕΠΟΜΕΝΗΣ, ΑΛΛΑΓΗΣ | AB2: ΑΠΟΦΑΣΕΙΣ ΠΑΡΑΤΗΡΗΣΕΙΣ | AC2: Α.Μ. | AD2: UNIQUE
A3: =--SUBTOTAL(3,$B$2:B2) -> 1 | B3: 1044 | C3: ΚΕ-Δ | D3: 14201 | E3: ΑΛΕΒΙΖΟΠΟΥΛΟΥ | F3: ΟΛΓΑ | G3: ΒΑΣΙΛΕΙΟΣ | H3: =TRIM($E3)&" "&TRIM($F3) -> ΑΛΕΒΙΖΟΠΟΥΛΟΥ ΟΛΓΑ | I3: =TRIM($H3)&" - "&TRIM($O3)&" ("&TRIM(C3)&")" -> ΑΛΕΒΙΖΟΠΟΥΛΟΥ ΟΛΓΑ - ΤΕ ΜΗΧΑΝΙΚΩΝ (ΚΕ-Δ) | J3: 154885734 | K3: 08:00 - 16:00 | L3: 2294440030 | M3: 2102464843 | N3: 6972406536 | O3: ΤΕ ΜΗΧΑΝΙΚΩΝ | P3: Μ | Q3: Μηχανικός | R3: ΙΔΟΧ | S3: oalevizopoulou@civilprotection.gr | T3: taefkaa.alevizopoulou@gmail.com | U3: ΤΑΕΦΚ ΑΑ | V3: ΕΥΔΕ ΚΣΕΣΠ | W3: ΔΑΕΦΚ-ΚΕ ΤΜΗΜΑ Δ | X3: 3 | AA3: 45561 | AC3: 12421 | AD3: 1060
A4: =--SUBTOTAL(3,$B$2:B3) -> 2 | B4: 1429 | C4: ΆΛΛΟ | D4: 14263 | E4: ΑΛΕΞΟΠΟΥΛΟΣ | F4: ΔΙΟΝΥΣΙΟΣ | G4: ΑΘΑΝΑΣΙΟΣ | H4: =TRIM($E4)&" "&TRIM($F4) -> ΑΛΕΞΟΠΟΥΛΟΣ ΔΙΟΝΥΣΙΟΣ | I4: =TRIM($H4)&" - "&TRIM($O4)&" ("&TRIM(W4)&")" -> ΑΛΕΞΟΠΟΥΛΟΣ ΔΙΟΝΥΣΙΟΣ - ΤΕ ΜΗΧΑΝΙΚΩΝ (ΠΑΡΑΙΤΗΘΗΚΕ) | M4: _ | N4: 6973414947 | O4: ΤΕ ΜΗΧΑΝΙΚΩΝ | P4: =LEFT(Q4,1) -> Μ | Q4: Μηχανικός | R4: ΙΔΟΧ | S4: _ | T4: _ | U4: ΓΔΑΕΦΚ | V4: Δ20-ΔΙΕΥΘΥΝΣΗ ΛΙΜΕΝΙΚΩΝ ΥΠΟΔΟΜΩΝ | W4: ΠΑΡΑΙΤΗΘΗΚΕ | X4: 0 | AB4: ΕΧΕΙ ΠΑΡΑΙΤΗΘΕΙ ΕΊΝΑΙ ΣΤΗ ΔΙΑΠΙΣΤΩΤΙΚΗ, ΑΛΛΑ ΌΧΙ ΣΤΟ EXCEL ΤΗΣ ΓΔΑΕΦΚ - ΠΡΟΣΛΗΨΗ ΓΙΑ ΤΟ ΤΑΕΦΚ ΖΑΚΥΝΘΟΥ | AC4: 12723 | AD4: 1062
A5: =--SUBTOTAL(3,$B$2:B4) -> 3 | B5: 1046 | C5: ΚΕ | D5: 14381 | E5: ΑΝΑΣΤΑΣΑΚΗΣ | F5: ΔΗΜΗΤΡΙΟΣ | G5: ΔΗΜΗΤΡΙΟΣ | H5: =TRIM($E5)&" "&TRIM($F5) -> ΑΝΑΣΤΑΣΑΚΗΣ ΔΗΜΗΤΡΙΟΣ | I5: =TRIM($H5)&" - "&TRIM($O5)&" ("&TRIM(C5)&")" -> ΑΝΑΣΤΑΣΑΚΗΣ ΔΗΜΗΤΡΙΟΣ - ΠΕ ΜΗΧΑΝΙΚΩΝ (ΚΕ) | J5: 123042680 | K5: _ | L5: 210 6999418 | M5: 2102464843 | N5: 6936854170 | O5: ΠΕ ΜΗΧΑΝΙΚΩΝ | P5: Μ | Q5: Μηχανικός | R5: ΙΔΟΧ | S5: _ | T5: d.anastasakis@ggde.gr | U5: ΔΑΕΦΚ ΚΕ-Δ26 | V5: Δ17-ΔΙΕΥΘΥΝΣΗ ΛΕΙΤΟΥΡΓΙΑΣ, ΣΥΝΤΗΡΗΣΗΣ ΚΑΙ ΕΚΜΕΤΑΛΛΕΥΣΗΣ ΣΥΓΚΟΙΝΩΝΙΑΚΩΝ ΥΠΟΔΟΜΩΝ ΜΕ ΣΥΜΒΑΣΗ ΠΑΡΑΧΩΡΗΣΗΣ | W5: ΔΑΕΦΚ-ΚΕ | X5: 3 | AA5: 45219 | AB5: Δ17-ΔΙΕΥΘΥΝΣΗ ΛΕΙΤΟΥΡΓΙΑΣ, ΣΥΝΤΗΡΗΣΗΣ ΚΑΙ ΕΚΜΕΤΑΛΛΕΥΣΗΣ ΣΥΓΚΟΙΝΩΝΙΑΚΩΝ ΥΠΟΔΟΜΩΝ ΜΕ ΣΥΜΒΑΣΗ ΠΑΡΑΧΩΡΗΣΗΣ | AC5: 12854 | AD5: 1064
A6: =--SUBTOTAL(3,$B$2:B5) -> 4 | B6: 1432 | C6: ΆΛΛΟ | D6: 13113 | E6: ΑΝΑΣΤΑΣΟΠΟΥΛΟΣ | F6: ΙΩΑΝΝΗΣ | G6: ΔΗΜΗΤΡΙΟΣ | H6: =TRIM($E6)&" "&TRIM($F6) -> ΑΝΑΣΤΑΣΟΠΟΥΛΟΣ ΙΩΑΝΝΗΣ | I6: =TRIM($H6)&" - "&TRIM($O6)&" ("&TRIM(W6)&")" -> ΑΝΑΣΤΑΣΟΠΟΥΛΟΣ ΙΩΑΝΝΗΣ - ΠΕ ΑΡΧ. ΜΗΧ. (ΑΠΟΛΥΘΗΚΕ) | M6: _ | N6: _ | O6: ΠΕ ΑΡΧ. ΜΗΧ. | P6: =LEFT(Q6,1) -> Μ | Q6: Μηχανικός | R6: ΙΔΑΧ | S6: _ | T6: _ | U6: ΔΑΕΦΚ ΚΕ-Δ26 (ΤΜΗΜΑ ΣΥΝΤΟΝΙΣΜΟΥ, ΣΧΕΔΙΑΣΜΟΥ ΚΑΙ ΜΕΛΕΤΩΝ) | W6: ΑΠΟΛΥΘΗΚΕ | X6: 0 | AB6: ΛΕΙΠΕΙ ΧΡΟΝΙΑ | AC6: 12143 | AD6: 1066
A7: =--SUBTOTAL(3,$B$2:B6) -> 5 | B7: 1053 | C7: ΆΛΛΟ | D7: 14431 | E7: ΓΙΑΝΝΑΚΟΠΟΥΛΟΥ | F7: ΘΕΟΔΩΡΑ | G7: ΒΑΣΙΛΕΙΟΣ | H7: =TRIM($E7)&" "&TRIM($F7) -> ΓΙΑΝΝΑΚΟΠΟΥΛΟΥ ΘΕΟΔΩΡΑ | I7: =TRIM($H7)&" - "&TRIM($O7)&" ("&TRIM(W7)&")" -> ΓΙΑΝΝΑΚΟΠΟΥΛΟΥ ΘΕΟΔΩΡΑ - ΠΕ ΔΙΟΙΚ.-ΟΙΚ. (ΣΥΝΤΑΞΗ) | J7: 046578687 | K7: _ | L7: _ | M7: 2107608495 | N7: 6932711139 | O7: ΠΕ ΔΙΟΙΚ.-ΟΙΚ. | P7: =LEFT(Q7,1) -> Δ | Q7: Διοικητικός | R7: ΙΔΟΧ | S7: _ | T7: _ | U7: ΔΑΕΦΚ ΚΕ-Δ26 | V7: Δ2-ΔΙΕΥΘΥΝΣΗ ΟΙΚΟΝΟΜΙΚΗΣ ΔΙΑΧΕΙΡΙΣΗΣ | W7: ΣΥΝΤΑΞΗ | X7: 0 | AA7: 45212 | AB7: ΕΧΕΙ ΠΑΡΑΙΤΗΘΕΙ | AC7: 12668 | AD7: 1067
A8: =--SUBTOTAL(3,$B$2:B7) -> 6 | B8: 1125 | C8: ΆΛΛΟ | D8: 14150 | E8: ΓΟΥΝΑΡΙΔΟΥ | F8: ΕΥΧΑΡΙΣ | G8: ΓΕΩΡΓΙΟΣ | H8: =TRIM($E8)&" "&TRIM($F8) -> ΓΟΥΝΑΡΙΔΟΥ ΕΥΧΑΡΙΣ | I8: =TRIM($H8)&" - "&TRIM($O8)&" ("&TRIM(W8)&")" -> ΓΟΥΝΑΡΙΔΟΥ ΕΥΧΑΡΙΣ - ΠΕ ΠΟΛ. ΜΗΧ. (ΣΥΝΤΑΞΗ) | J8: 041354039 | K8: 2310 416572 | L8: 2310 416572 | M8: 2310345220 | N8: 6974494940 | O8: ΠΕ ΠΟΛ. ΜΗΧ. | P8: =LEFT(Q8,1) -> Μ | Q8: Μηχανικός | R8: ΙΔΑΧ | S8: _ | T8: efi.gouna@gmail.com | U8: ΔΑΕΦΚ ΒΕ-Δ28 (ΤΜΗΜΑ ΣΥΝΤΟΝΙΣΜΟΥ, ΣΧΕΔΙΑΣΜΟΥ ΚΑΙ ΜΕΛΕΤΩΝ) | W8: ΣΥΝΤΑΞΗ | X8: 0 | AA8: 45320 | AB8: ΣΥΝΤΑΞΗ | AC8: 12144 | AD8: 1069
A9: =--SUBTOTAL(3,$B$2:B8) -> 7 | B9: 1245 | C9: ΗΡ | D9: 14506 | E9: ΔΑΚΙΔΗΣ | F9: ΧΡΗΣΤΟΣ | G9: ΕΛΕΥΘΕΡΙΟΣ | H9: ΔΑΚΙΔΗΣ ΧΡΗΣΤΟΣ | I9: ΔΑΚΙΔΗΣ ΧΡΗΣΤΟΣ - ΠΕ ΠΟΛ. ΜΗΧ. (ΤΑΕΦΚ ΗΡΑΚΛΕΙΟΥ) | J9: 159438610 | K9: 07:00 - 15:00 | L9: 2810311318 | M9: _ | N9: 6949027222 | O9: ΠΕ ΠΟΛ. ΜΗΧ. | P9: Μ | Q9: Μηχανικός | R9: ΙΔΟΧ | S9: _ | T9: xristos.dakidis@gmail.com | U9: ΤΑΕΦΚ Π.Ε. ΗΡΑΚΛΕΙΟΥ | W9: ΤΑΕΦΚ ΗΡΑΚΛΕΙΟΥ | X9: 1 | AA9: 45514 | AB9: ΕΧΕΙ ΠΑΡΑΙΤΗΘΕΙ | AC9: 12167 | AD9: 1433
A10: =--SUBTOTAL(3,$B$2:B9) -> 8 | B10: 1336 | C10: ΆΛΛΟ | D10: 12182 | E10: ΔΑΛΕΖΙΟΣ | F10: ΑΧΙΛΛΕΑΣ | G10: ΑΓΓΕΛΟΣ | H10: =TRIM($E10)&" "&TRIM($F10) -> ΔΑΛΕΖΙΟΣ ΑΧΙΛΛΕΑΣ | I10: =TRIM($H10)&" - "&TRIM($O10)&" ("&TRIM(W10)&")" -> ΔΑΛΕΖΙΟΣ ΑΧΙΛΛΕΑΣ - ΠΕ ΤΟΠ. ΜΗΧ. (ΣΥΝΤΑΞΗ) | J10: 027767862 | K10: 2131523756 | L10: 2131523756 | M10: _ | N10: 6974378663 | O10: ΠΕ ΤΟΠ. ΜΗΧ. | P10: =LEFT(Q10,1) -> Μ | Q10: Μηχανικός | R10: ΙΔΑΧ | S10: adalezios@civilprotection.gr | T10: axilleas.dale@yahoo.gr | U10: ΔΑΕΦΚ ΚΕ-Δ26 (ΤΜΗΜΑ ΔΙΑΧΕΙΡΙΣΗΣ ΠΡΟΣΩΡΙΝΗΣ ΣΤΕΓΑΣΗΣ ΚΑΙ ΕΞΟΠΛΙΣΜΟΥ) | W10: ΣΥΝΤΑΞΗ | X10: 13 | AA10: 44848 | AB10: ΣΥΝΤΑΞΗ | AC10: 14402 | AD10: 1085
A11: =--SUBTOTAL(3,$B$2:B10) -> 9 | B11: 1058 | C11: ΆΛΛΟ | D11: 7488 | E11: ΔΕΔΕ | F11: ΙΩΑΝΝΑ | G11: ΣΩΤΗΡΙΟΣ | H11: =TRIM($E11)&" "&TRIM($F11) -> ΔΕΔΕ ΙΩΑΝΝΑ | I11: =TRIM($H11)&" - "&TRIM($O11)&" ("&TRIM(W11)&")" -> ΔΕΔΕ ΙΩΑΝΝΑ - ΠΕ ΓΕΩΤΕΧΝΙΚΩΝ (ΟΑΣΠ) | J11: 127909939 | K11: _ | L11: _ | M11: 2107608495 | N11: 6977216272 | O11: ΠΕ ΓΕΩΤΕΧΝΙΚΩΝ | P11: =LEFT(Q11,1) -> Δ | Q11: Διοικητικός | R11: ΜΟΝΙΜΟΣ | S11: _ | T11: _ | U11: ΔΑΕΦΚ ΚΕ-Δ26 | V11: ΟΑΣΠ | W11: ΟΑΣΠ | X11: 0 | AA11: 45078 | AB11: ΟΑΣΠ | AC11: 12227 | AD11: 1087
A12: =--SUBTOTAL(3,$B$2:B11) -> 10 | B12: 1130 | C12: ΒΕ | D12: 14465 | E12: ΔΗΜΟΣΘΕΝΗΣ | F12: ΒΛΑΣΙΟΣ | G12: ΓΕΩΡΓΙΟΣ | H12: =TRIM($E12)&" "&TRIM($F12) -> ΔΗΜΟΣΘΕΝΗΣ ΒΛΑΣΙΟΣ | I12: =TRIM($H12)&" - "&TRIM($O12)&" ("&TRIM(C12)&")" -> ΔΗΜΟΣΘΕΝΗΣ ΒΛΑΣΙΟΣ - ΠΕ ΠΟΛ. ΜΗΧ. (ΒΕ) | J12: 122038643 | K12: 08:30 - 16:30 | M12: 2310 428468 | N12: 6985709513 | O12: ΠΕ ΠΟΛ. ΜΗΧ. | P12: Μ | Q12: Μηχανικός | R12: ΙΔΟΧ | S12: vdimosthenis@civilprotection.gr | T12: vlasis.d@gmail.com | U12: ΔΑΕΦΚ ΒΕ-Δ28 | W12: ΔΑΕΦΚ-ΒΕ | X12: 1 | AA12: 45309 | AB12: ΕΧΕΙ ΠΑΡΑΙΤΗΘΕΙ | AC12: 12661 | AD12: 1386
A13: =--SUBTOTAL(3,$B$2:B12) -> 11 | B13: 1313 | C13: ΚΕ-Β | D13: 5608 | E13: ΕΣΚΙΝΤΖΗΣ | F13: ΑΠΟΣΤΟΛΟΣ | G13: ΕΥΑΓΓΕΛΟΣ | H13: =TRIM($E13)&" "&TRIM($F13) -> ΕΣΚΙΝΤΖΗΣ ΑΠΟΣΤΟΛΟΣ | I13: =TRIM($H13)&" - "&TRIM($O13)&" ("&TRIM(C13)&")" -> ΕΣΚΙΝΤΖΗΣ ΑΠΟΣΤΟΛΟΣ - ΤΕ ΕΡΓΟΔΗΓΩΝ (Χ.ΠΤ.) (ΚΕ-Β) | J13: 026883365 | K13: 07:00 - 15:00 | L13: 210 8704720 | M13: _ | N13: 6947244486 | O13: ΤΕ ΕΡΓΟΔΗΓΩΝ (Χ.ΠΤ.) | P13: Δ | Q13: Διοικητικός | R13: ΜΟΝΙΜΟΣ | S13: _ | T13: tolisesk@hotmail.com | U13: ΔΑΕΦΚ ΚΕ-Δ26 (ΤΜΗΜΑ ΠΡΟΓΡΑΜΜΑΤΙΣΜΟΥ, ΑΠΟΚΑΤΑΣΤΑΣΗΣ ΚΑΙ ΕΚΠΑΙΔΕΥΣΗΣ) | W13: ΔΑΕΦΚ-ΚΕ ΤΜΗΜΑ Β | X13: 17 | Y13: 44926 | AA13: 44926 | AB13: ΣΥΝΤΑΞΗ | AC13: 13572 | AD13: 1292
A14: =--SUBTOTAL(3,$B$2:B13) -> 12 | B14: 1060 | C14: ΆΛΛΟ | D14: 12421 | E14: ΖΑΓΟΡΑ | F14: ΓΑΒΡΙΕΛΑ | G14: ΚΩΝΣΤΑΝΤΙΝΟΣ | H14: =TRIM($E14)&" "&TRIM($F14) -> ΖΑΓΟΡΑ ΓΑΒΡΙΕΛΑ | I14: =TRIM($H14)&" - "&TRIM($O14)&" ("&TRIM(W14)&")" -> ΖΑΓΟΡΑ ΓΑΒΡΙΕΛΑ - ΠΕ ΠΟΛ. ΜΗΧ. (ΟΑΣΠ) | J14: 071524425 | K14: _ | L14: _ | M14: 2106713188 | N14: 2108947655 | O14: ΠΕ ΠΟΛ. ΜΗΧ. | P14: =LEFT(Q14,1) -> Μ | Q14: Μηχανικός | R14: ΙΔΑΧ | S14: _ | T14: _ | U14: ΔΑΕΦΚ ΚΕ-Δ26 (ΤΜΗΜΑ ΣΥΝΤΟΝΙΣΜΟΥ, ΣΧΕΔΙΑΣΜΟΥ ΚΑΙ ΜΕΛΕΤΩΝ) | V14: ΟΑΣΠ | W14: ΟΑΣΠ | X14: 0 | AA14: 45240 | AB14: ΟΑΣΠ | AC14: 14257 | AD14: 1430
A15: =--SUBTOTAL(3,$B$2:B14) -> 13 | B15: 1064 | C15: ΆΛΛΟ | D15: 12854 | E15: ΙΩΑΚΕΙΜΙΔΟΥ | F15: ΑΝΑΣΤΑΣΙΑ | G15: ΝΙΚΟΛΑΟΣ | H15: =TRIM($E15)&" "&TRIM($F15) -> ΙΩΑΚΕΙΜΙΔΟΥ ΑΝΑΣΤΑΣΙΑ | I15: =TRIM($H15)&" - "&TRIM($O15)&" ("&TRIM(W15)&")" -> ΙΩΑΚΕΙΜΙΔΟΥ ΑΝΑΣΤΑΣΙΑ - ΠΕ ΤΟΠ. ΜΗΧ. (ΒΡΥΞΕΛΛΕΣ) | J15: 042273618 | K15: _ | L15: _ | M15: 2106713188 | N15: 2106526048 | O15: ΠΕ ΤΟΠ. ΜΗΧ. | P15: =LEFT(Q15,1) -> Μ | Q15: Μηχανικός | R15: ΙΔΑΧ | S15: _ | T15: _ | U15: ΔΑΕΦΚ ΚΕ-Δ26 (ΤΜΗΜΑ ΕΠΟΠΤΕΙΑΣ ΑΠΟΚΑΤΑΣΤΑΣΗΣ ΦΥΣΙΚΩΝ ΚΑΤΑΣΤΡΟΦΩΝ) | V15: ΒΡΥΞΕΛΛΕΣ | W15: ΒΡΥΞΕΛΛΕΣ | X15: 0 | AA15: 44930 | AB15: ΒΡΥΞΕΛΛΕΣ | AC15: 14459 | AD15: 1097
A16: =--SUBTOTAL(3,$B$2:B15) -> 14 | B16: 1067 | C16: ΆΛΛΟ | D16: 12668 | E16: ΚΑΡΑΓΙΑΝΝΙΔΗ | F16: ΕΥΤΥΧΙΑ | G16: ΑΡΙΣΤΟΤΕΛΗΣ | H16: =TRIM($E16)&" "&TRIM($F16) -> ΚΑΡΑΓΙΑΝΝΙΔΗ ΕΥΤΥΧΙΑ | I16: =TRIM($H16)&" - "&TRIM($O16)&" ("&TRIM(W16)&")" -> ΚΑΡΑΓΙΑΝΝΙΔΗ ΕΥΤΥΧΙΑ - ΤΕ ΜΗΧΑΝΙΚΩΝ (ΔΙΑΧΕΙΡΙΣΤΙΚΗ ΑΡΧΗ) | J16: 032702434 | K16: _ | L16: _ | M16: 2106713188 | N16: 2107771508 | O16: ΤΕ ΜΗΧΑΝΙΚΩΝ | P16: =LEFT(Q16,1) -> Μ | Q16: Μηχανικός | R16: ΙΔΑΧ | S16: _ | T16: _ | U16: ΓΔΑΕΦΚ | V16: ΔΙΑΧΕΙΡΙΣΤΙΚΗ ΑΡΧΗ | W16: ΔΙΑΧΕΙΡΙΣΤΙΚΗ ΑΡΧΗ | X16: 11 | AA16: 45260 | AB16: ΔΙΑΧΕΙΡΙΣΤΙΚΗ ΑΡΧΗ | AC16: 14476 | AD16: 1234
A17: =--SUBTOTAL(3,$B$2:B16) -> 15 | B17: 1138 | C17: ΆΛΛΟ | D17: 14450 | E17: ΚΑΡΑΜΠΑΣΗΣ | F17: ΧΡΗΣΤΟΣ | G17: ΕΥΣΤΑΘΙΟΣ | H17: ΚΑΡΑΜΠΑΣΗΣ ΧΡΗΣΤΟΣ | I17: ΚΑΡΑΜΠΑΣΗΣ ΧΡΗΣΤΟΣ - ΠΕ ΠΟΛ. ΜΗΧ. (ΔΑΕΦΚ-ΒΕ) | J17: 047777569 | K17: 08:00 - 16:00 | L17: 2310 414840 | M17: 2310452083 | N17: 6947449447 | O17: ΠΕ ΠΟΛ. ΜΗΧ. | P17: Μ | Q17: Μηχανικός | R17: ΙΔΟΧ | S17: chkarampasis@civilprotection.gr | T17: rythmosk@otenet.gr | U17: ΔΑΕΦΚ ΒΕ-Δ28 | W17: ΔΑΕΦΚ-ΒΕ | X17: 1 | AA17: 45214 | AB17: ΕΧΕΙ ΠΑΡΑΙΤΗΘΕΙ | AC17: 12876 | AD17: 1103
A18: =--SUBTOTAL(3,$B$2:B17) -> 16 | B18: 1378 | C18: ΚΕ-Δ | D18: 5748 | E18: ΜΠΑΜΠΙΛΗ | F18: ΒΙΚΤΩΡΙΑ | G18: ΑΘΑΝΑΣΙΟΣ | H18: =TRIM($E18)&" "&TRIM($F18) -> ΜΠΑΜΠΙΛΗ ΒΙΚΤΩΡΙΑ | I18: =TRIM($H18)&" - "&TRIM($O18)&" ("&TRIM(C18)&")" -> ΜΠΑΜΠΙΛΗ ΒΙΚΤΩΡΙΑ - ΠΕ ΠΟΛ. ΜΗΧ. (ΚΕ-Δ) | J18: 041596329 | K18: 08:00 - 16:00 | L18: 210 8704717, 210 64 60 321 | M18: _ | N18: 6944393637 | O18: ΠΕ ΠΟΛ. ΜΗΧ. | P18: Μ | Q18: Μηχανικός | R18: ΜΟΝΙΜΟΣ | S18: vmpampili@civilprotection.gr | T18: viktoriababili@gmail.com | U18: ΔΑΕΦΚ ΚΕ-Δ26 (ΤΜΗΜΑ ΕΠΟΠΤΕΙΑΣ ΑΠΟΚΑΤΑΣΤΑΣΗΣ ΦΥΣΙΚΩΝ ΚΑΤΑΣΤΡΟΦΩΝ) | W18: ΔΑΕΦΚ-ΚΕ ΤΜΗΜΑ Δ | X18: 17 | AA18: 44949 | AB18: ΣΥΝΤΑΞΗ | AC18: 5059 | AD18: 1104
A19: =--SUBTOTAL(3,$B$2:B18) -> 17 | B19: 1433 | C19: ΆΛΛΟ | D19: 14268 | E19: ΜΠΑΡΔΗΣ | F19: ΓΕΩΡΓΙΟΣ | G19: ΣΤΑΥΡΟΣ | H19: ΜΠΑΡΔΗΣ ΓΕΩΡΓΙΟΣ | I19: ΜΠΑΡΔΗΣ ΓΕΩΡΓΙΟΣ - ΠΕ ΜΗΧ. ΠΕΡΙΒΑΛ. (ΤΑΕΦΚ-ΑΑ) | J19: 145864882 | K19: 07:30 - 15:30 | L19: 2294 440030 | M19: _ | N19: 6976140354 | O19: ΠΕ ΜΗΧ. ΠΕΡΙΒΑΛ. | P19: Μ | Q19: Μηχανικός | R19: ΙΔΟΧ | S19: gmpardis@civilprotection.gr | T19: bardisge@gmail.com | U19: ΤΑΕΦΚ ΑΑ | W19: ΤΑΕΦΚ-ΑΑ | X19: 5 | AA19: 45017 | AB19: ΕΧΕΙ ΠΑΡΑΙΤΗΘΕΙ | AC19: 14365 | AD19: 1107
A20: =--SUBTOTAL(3,$B$2:B19) -> 18 | C20: ΑΑ | D20: 14235 | E20: ΜΠΟΥΣΜΠΟΥΡΕΛΗ | F20: ΠΕΤΡΟΥΛΑ | G20: ΚΩΝΣΤΑΝΤΙΝΟΣ | H20: ΜΠΟΥΣΜΠΟΥΡΕΛΗ ΠΕΤΡΟΥΛΑ | I20: ΜΠΟΥΣΜΠΟΥΡΕΛΗ ΠΕΤΡΟΥΛΑ - ΠΕ ΑΡΧ. ΜΗΧ. (ΑΑ) | J20: 106578893 | K20: 07:30 - 15:30 | L20: 2294 440030 | M20: 2109766841 | N20: 6974072869 | O20: ΠΕ ΑΡΧ. ΜΗΧ. | P20: Μ | Q20: Μηχανικός | R20: ΙΔΟΧ | S20: pmpousmpoureli@civilprotection.gr | T20: petroula.b@gmail.com | U20: ΤΑΕΦΚ ΑΑ | W20: ΤΑΕΦΚ-ΑΑ | X20: 5 | AA20: 44891 | AB20: ΕΧΕΙ ΠΑΡΑΙΤΗΘΕΙ | AC20: 14274 | AD20: 1415
A21: =--SUBTOTAL(3,$B$2:B20) -> 18 | B21: 1085 | C21: ΆΛΛΟ | D21: 12167 | E21: ΜΩΚΟΣ | F21: ΒΑΣΙΛΕΙΟΣ | G21: ΓΕΩΡΓΙΟΣ | H21: =TRIM($E21)&" "&TRIM($F21) -> ΜΩΚΟΣ ΒΑΣΙΛΕΙΟΣ | I21: =TRIM($H21)&" - "&TRIM($O21)&" ("&TRIM(W21)&")" -> ΜΩΚΟΣ ΒΑΣΙΛΕΙΟΣ - ΠΕ ΠΟΛ. ΜΗΧ. (ΟΑΣΠ) | J21: 102906367 | M21: _ | N21: _ | O21: ΠΕ ΠΟΛ. ΜΗΧ. | P21: =LEFT(Q21,1) -> Μ | Q21: Μηχανικός | R21: ΙΔΑΧ | S21: _ | T21: _ | U21: ΔΑΕΦΚ ΚΕ-Δ26 | W21: ΟΑΣΠ | X21: 0 | AB21: ΟΑΣΠ
A22: =--SUBTOTAL(3,$B$2:B21) -> 19 | B22: 1087 | C22: ΆΛΛΟ | D22: 14402 | E22: ΝΙΚΟΛΟΠΟΥΛΟΣ | F22: ΕΥΑΓΓΕΛΟΣ | G22: ΑΘΑΝΑΣΙΟΣ | H22: =TRIM($E22)&" "&TRIM($F22) -> ΝΙΚΟΛΟΠΟΥΛΟΣ ΕΥΑΓΓΕΛΟΣ | I22: =TRIM($H22)&" - "&TRIM($O22)&" ("&TRIM(W22)&")" -> ΝΙΚΟΛΟΠΟΥΛΟΣ ΕΥΑΓΓΕΛΟΣ - ΠΕ ΜΗΧΑΝΙΚΩΝ (ΓΡΑΦΕΙΟ ΥΠΟΥΡΓΟΥ) | J22: 160386034 | K22: _ | L22: _ | M22: _ | N22: 6970130611 | O22: ΠΕ ΜΗΧΑΝΙΚΩΝ | P22: =LEFT(Q22,1) -> Μ | Q22: Μηχανικός | R22: ΙΔΟΧ | S22: _ | T22: nikolopoulosvagelis@gmail.com | U22: ΔΑΕΦΚ ΚΕ-Δ26 | V22: ΓΡΑΦΕΙΟ ΥΠΟΥΡΓΟΥ ΥΜΕ | W22: ΓΡΑΦΕΙΟ ΥΠΟΥΡΓΟΥ | X22: 1 | AA22: 45212 | AB22: ΓΡΑΦΕΙΟ ΥΠΟΥΡΓΟΥ ΥΜΕ
A23: =--SUBTOTAL(3,$B$2:B22) -> 20 | B23: 1382 | C23: ΚΕ-Δ | D23: 12441 | E23: ΠΑΠΑΕΥΘΥΜΙΟΥ-ΓΩΓΟΣ | F23: ΓΕΩΡΓΙΟΣ | G23: ΠΕΡΙΚΛΗΣ | H23: =TRIM($E23)&" "&TRIM($F23) -> ΠΑΠΑΕΥΘΥΜΙΟΥ-ΓΩΓΟΣ ΓΕΩΡΓΙΟΣ | I23: =TRIM($H23)&" - "&TRIM($O23)&" ("&TRIM(C23)&")" -> ΠΑΠΑΕΥΘΥΜΙΟΥ-ΓΩΓΟΣ ΓΕΩΡΓΙΟΣ - ΠΕ ΑΡΧ. ΜΗΧ. (ΚΕ-Δ) | J23: 027945394 | K23: 08:00 - 16:00 | L23: 210 8704744 | M23: _ | N23: 6948358027 | O23: ΠΕ ΑΡΧ. ΜΗΧ. | P23: Μ | Q23: Μηχανικός | R23: ΙΔΑΧ | S23: gpapaefthymiou@civilprotection.gr | T23: g.papaefthimiou@yas.gr | U23: ΔΑΕΦΚ ΚΕ-Δ26 (ΤΜΗΜΑ ΕΠΟΠΤΕΙΑΣ ΑΠΟΚΑΤΑΣΤΑΣΗΣ ΦΥΣΙΚΩΝ ΚΑΤΑΣΤΡΟΦΩΝ) | W23: ΔΑΕΦΚ-ΚΕ ΤΜΗΜΑ Δ | X23: 11 | AA23: 45217 | AB23: ΣΥΝΤΑΞΗ
A24: =--SUBTOTAL(3,$B$2:B23) -> 21 | B24: 1385 | C24: ΚΕ-Δ | D24: 14410 | E24: ΠΟΖΙΟΥ | F24: ΚΑΣΣΙΑΝΗ | G24: ΒΑΙΟΣ | H24: =TRIM($E24)&" "&TRIM($F24) -> ΠΟΖΙΟΥ ΚΑΣΣΙΑΝΗ | I24: =TRIM($H24)&" - "&TRIM($O24)&" ("&TRIM(C24)&")" -> ΠΟΖΙΟΥ ΚΑΣΣΙΑΝΗ - ΠΕ ΠΟΛ. ΜΗΧ. (ΚΕ-Δ) | J24: 116121655 | K24: 07:30 - 15:30 | L24: 210 64 49 502 | M24: _ | N24: 6984685650 | O24: ΠΕ ΠΟΛ. ΜΗΧ. | P24: Μ | Q24: Μηχανικός | R24: ΙΔΟΧ | S24: kpoziou@civilprotection.gr | T24: kasspoz@hotmail.com | U24: ΔΑΕΦΚ ΚΕ-Δ26 | V24: ΤΑΕΦΚ Π.Ε. ΗΡΑΚΛΕΙΟΥ - ΠΑΡ.ΚΑΘ. | W24: ΔΑΕΦΚ-ΚΕ ΤΜΗΜΑ Δ | X24: 1 | AA24: 45212 | AB24: ΕΧΕΙ ΠΑΡΑΙΤΗΘΕΙ
A25: =--SUBTOTAL(3,$B$2:B24) -> 22 | B25: 1292 | C25: ΆΛΛΟ | D25: 12661 | E25: ΠΟΙΜΕΝΙΔΟΥ | F25: ΚΥΡΙΑΚΗ | G25: ΘΕΜΙΣΤΟΚΛΗΣ | H25: =TRIM($E25)&" "&TRIM($F25) -> ΠΟΙΜΕΝΙΔΟΥ ΚΥΡΙΑΚΗ | I25: =TRIM($H25)&" - "&TRIM($O25)&" ("&TRIM(W25)&")" -> ΠΟΙΜΕΝΙΔΟΥ ΚΥΡΙΑΚΗ - ΠΕ ΠΟΛ. ΜΗΧ. (ΣΥΝΤΑΞΗ) | J25: 043933358 | K25: 210 64 53 706 | L25: 210 8704735 | M25: 2109567766 | N25: 6977010272 | O25: ΠΕ ΠΟΛ. ΜΗΧ. | P25: =LEFT(Q25,1) -> Μ | Q25: Μηχανικός | R25: ΙΔΑΧ | S25: kpoimenidou@civilprotection.gr | T25: pimenidou@gmail.com | U25: ΔΑΕΦΚ ΚΕ-Δ26 (ΤΜΗΜΑ ΕΠΟΠΤΕΙΑΣ ΑΠΟΚΑΤΑΣΤΑΣΗΣ ΦΥΣΙΚΩΝ ΚΑΤΑΣΤΡΟΦΩΝ) | W25: ΣΥΝΤΑΞΗ | X25: 11 | AA25: 45273 | AB25: ΣΥΝΤΑΞΗ | AC25: 12284 | AD25: 1346
A26: =--SUBTOTAL(3,$B$2:B25) -> 23 | B26: 1430 | C26: ΆΛΛΟ | D26: 13572 | E26: ΠΥΡΟΒΟΛΑΚΗΣ | F26: ΙΩΑΝΝΗΣ | G26: ΕΜΜΑΝΟΥΗΛ | H26: =TRIM($E26)&" "&TRIM($F26) -> ΠΥΡΟΒΟΛΑΚΗΣ ΙΩΑΝΝΗΣ | I26: =TRIM($H26)&" - "&TRIM($O26)&" ("&TRIM(W26)&")" -> ΠΥΡΟΒΟΛΑΚΗΣ ΙΩΑΝΝΗΣ - ΠΕ ΠΟΛ. ΜΗΧ. (ΔΙΑΧΕΙΡΙΣΤΙΚΗ ΑΡΧΗ) | J26: 034725314 | K26: _ | L26: 2106930186 | M26: _ | N26: 6974489739 | O26: ΠΕ ΠΟΛ. ΜΗΧ. | P26: =LEFT(Q26,1) -> Μ | Q26: Μηχανικός | R26: ΙΔΑΧ | S26: _ | T26: ypyros@gmail.com | U26: ΔΑΕΦΚ ΚΕ-Δ26 (ΤΜΗΜΑ ΣΥΝΤΟΝΙΣΜΟΥ, ΣΧΕΔΙΑΣΜΟΥ ΚΑΙ ΜΕΛΕΤΩΝ) | W26: ΔΙΑΧΕΙΡΙΣΤΙΚΗ ΑΡΧΗ | X26: 11 | AA26: 45159 | AC26: 14201 | AD26: 1044
A27: =--SUBTOTAL(3,$B$2:B26) -> 24 | B27: 1097 | C27: ΆΛΛΟ | D27: 14257 | E27: ΣΑΤΛΑΝΗ | F27: ΚΩΝΣΤΑΝΤΙΝΑ | G27: ΝΙΚΟΛΑΟΣ | H27: =TRIM($E27)&" "&TRIM($F27) -> ΣΑΤΛΑΝΗ ΚΩΝΣΤΑΝΤΙΝΑ | I27: =TRIM($H27)&" - "&TRIM($O27)&" ("&TRIM(W27)&")" -> ΣΑΤΛΑΝΗ ΚΩΝΣΤΑΝΤΙΝΑ - ΠΕ ΔΙΟΙΚΗΤΙΚΟΥ (ΠΑΡΑΙΤΗΘΗΚΕ) | M27: _ | N27: 6982515353 | O27: ΠΕ ΔΙΟΙΚΗΤΙΚΟΥ | P27: =LEFT(Q27,1) -> Δ | Q27: Διοικητικός | R27: ΙΔΟΧ | S27: _ | T27: Konsatlani@yahoo.com | U27: ΓΔΑΕΦΚ | V27: Δ2-ΔΙΕΥΘΥΝΣΗ ΟΙΚΟΝΟΜΙΚΗΣ ΔΙΑΧΕΙΡΙΣΗΣ | W27: ΠΑΡΑΙΤΗΘΗΚΕ | X27: 0 | AB27: ΕΧΕΙ ΠΑΡΑΙΤΗΘΕΙ ΕΊΝΑΙ ΣΤΗ ΔΙΑΠΙΣΤΩΤΙΚΗ, ΑΛΛΑ ΌΧΙ ΣΤΟ EXCEL ΤΗΣ ΓΔΑΕΦΚ - ΠΡΟΣΛΗΨΗ ΓΙΑ ΤΟ ΤΑΕΦΚ ΖΑΚΥΝΘΟΥ | AC27: 14381 | AD27: 1046
A28: =--SUBTOTAL(3,$B$2:B27) -> 25 | B28: 1234 | C28: ΆΛΛΟ | D28: 14317 | E28: ΣΙΔΗΡΟΠΟΥΛΟΣ | F28: ΑΛΕΞΑΝΔΡΟΣ | G28: ΔΗΜΗΤΡΙΟΣ | H28: ΣΙΔΗΡΟΠΟΥΛΟΣ ΑΛΕΞΑΝΔΡΟΣ | I28: ΣΙΔΗΡΟΠΟΥΛΟΣ ΑΛΕΞΑΝΔΡΟΣ - ΠΕ ΜΗΧ. ΠΑΡ. (ΔΑΕΦΚ-ΒΕ) | J28: 064254688 | K28: 09:00 - 17:00 | L28: 2310 427952 | M28: 2410625791 | N28: 6949453697 | O28: ΠΕ ΜΗΧ. ΠΑΡ. | P28: Μ | Q28: Μηχανικός | R28: ΙΔΟΧ | S28: asidiropoulos@civilprotection.gr | T28: alexandersid13@gmail.com | U28: ΤΑΕΦΚ ΠΕ ΧΑΛΚΙΔΙΚΗΣ | V28: ΔΑΕΦΚ Β.Ε. (Δ28) - ΠΑΡ.ΚΑΘ. | W28: ΔΑΕΦΚ-ΒΕ | X28: 8 | AA28: 45503 | AB28: ΕΧΕΙ ΠΑΡΑΙΤΗΘΕΙ | AC28: 14325 | AD28: 1294
A29: =--SUBTOTAL(3,$B$2:B28) -> 26 | B29: 1103 | C29: ΆΛΛΟ | D29: 14459 | E29: ΣΚΛΙΑΜΗ | F29: ΑΙΚΑΤΕΡΙΝΗ | G29: ΠΑΡΑΣΚΕΥΑΣ | H29: =TRIM($E29)&" "&TRIM($F29) -> ΣΚΛΙΑΜΗ ΑΙΚΑΤΕΡΙΝΗ | I29: =TRIM($H29)&" - "&TRIM($O29)&" ("&TRIM(W29)&")" -> ΣΚΛΙΑΜΗ ΑΙΚΑΤΕΡΙΝΗ - ΠΕ ΜΗΧΑΝΙΚΩΝ (ΠΑΡΑΙΤΗΘΗΚΕ) | J29: 130246917 | K29: _ | L29: _ | M29: 2106617928 | N29: 6947199772 | O29: ΠΕ ΜΗΧΑΝΙΚΩΝ | P29: =LEFT(Q29,1) -> Μ | Q29: Μηχανικός | R29: ΙΔΟΧ | S29: _ | T29: _ | U29: ΔΑΕΦΚ ΚΕ-Δ26 | V29: ΓΡΑΦΕΙΟ ΥΠΟΥΡΓΟΥ ΥΜΕ | W29: ΠΑΡΑΙΤΗΘΗΚΕ | X29: 0 | AA29: 45252 | AB29: ΕΧΕΙ ΠΑΡΑΙΤΗΘΕΙ | AC29: 5608 | AD29: 1313
A30: =--SUBTOTAL(3,$B$2:B29) -> 27 | B30: 1104 | C30: ΆΛΛΟ | D30: 14476 | E30: ΣΟΥΓΛΕΡΗ | F30: ΙΩΑΝΝΑ | G30: ΕΥΑΓΓΕΛΟΣ | H30: =TRIM($E30)&" "&TRIM($F30) -> ΣΟΥΓΛΕΡΗ ΙΩΑΝΝΑ | I30: =TRIM($H30)&" - "&TRIM($O30)&" ("&TRIM(W30)&")" -> ΣΟΥΓΛΕΡΗ ΙΩΑΝΝΑ - ΠΕ ΠΟΛ. ΜΗΧ. (ΠΑΡΑΙΤΗΘΗΚΕ) | J30: 145036517 | K30: _ | L30: 2610 589122 | M30: 2610641041 | N30: 6978010154 | O30: ΠΕ ΠΟΛ. ΜΗΧ. | P30: =LEFT(Q30,1) -> Μ | Q30: Μηχανικός | R30: ΙΔΟΧ | S30: isougleri@civilprotection.gr | T30: ioanna.sougleri@gmail.com | U30: ΔΑΕΦΚ ΔΕ-Δ27 | W30: ΠΑΡΑΙΤΗΘΗΚΕ | X30: 0 | AA30: 45442 | AB30: ΕΧΕΙ ΠΑΡΑΙΤΗΘΕΙ | AC30: 102917 | AD30: 1345
A31: =--SUBTOTAL(3,$B$2:B30) -> 28 | B31: 1294 | C31: ΚΕ-Α | D31: 14325 | E31: ΣΤΡΑΤΙΔΑΚΗ | F31: ΚΥΡΙΑΚΗ | G31: ΓΕΩΡΓΙΟΣ | H31: =TRIM($E31)&" "&TRIM($F31) -> ΣΤΡΑΤΙΔΑΚΗ ΚΥΡΙΑΚΗ | I31: =TRIM($H31)&" - "&TRIM($O31)&" ("&TRIM(C31)&")" -> ΣΤΡΑΤΙΔΑΚΗ ΚΥΡΙΑΚΗ - ΤΕ ΜΗΧΑΝΙΚΩΝ (ΚΕ-Α) | J31: 151800701 | K31: 07:30 - 15:30 | L31: 2108704708 | M31: _ | N31: 6948851335 | O31: ΤΕ ΜΗΧΑΝΙΚΩΝ | P31: Μ | Q31: Μηχανικός | R31: ΙΔΟΧ | S31: kstratidaki@civilprotection.gr | T31: kstratidaki@yahoo.gr | U31: ΔΑΕΦΚ ΚΕ-Δ26 | W31: ΔΑΕΦΚ-ΚΕ ΤΜΗΜΑ Α | X31: 4 | AA31: 45500 | AB31: ΕΧΕΙ ΠΑΡΑΙΤΗΘΕΙ | AC31: 5748 | AD31: 1378
A32: =--SUBTOTAL(3,$B$2:B31) -> 29 | B32: 1025 | C32: ΆΛΛΟ | D32: 14365 | E32: ΤΣΙΛΙΜΑΝΤΟΥ | F32: ΕΛΙΣΑΒΕΤ | G32: ΚΩΝΣΤΑΝΤΙΝΟΣ | H32: =TRIM($E32)&" "&TRIM($F32) -> ΤΣΙΛΙΜΑΝΤΟΥ ΕΛΙΣΑΒΕΤ | I32: =TRIM($H32)&" - "&TRIM($O32)&" ("&TRIM(W32)&")" -> ΤΣΙΛΙΜΑΝΤΟΥ ΕΛΙΣΑΒΕΤ - ΠΕ ΜΗΧΑΝΙΚΩΝ (ΠΑΡΑΙΤΗΘΗΚΕ) | J32: 126679566 | K32: 210 6417640 | L32: 210 6417640 | M32: 2106617928 | N32: 6938030875 | O32: ΠΕ ΜΗΧΑΝΙΚΩΝ | P32: =LEFT(Q32,1) -> Μ | Q32: Μηχανικός | R32: ΙΔΟΧ | S32: _ | T32: _ | U32: ΔΑΕΦΚ ΚΕ-Δ26 | V32: Δ25-ΔΙΕΥΘΥΝΣΗ ΑΠΑΛΛΟΤΡΙΩΣΕΩΝ, ΤΟΠΟΓΡΑΦΗΣΕΩΝ ΚΑΙ ΓΕΩΠΛΗΡΟΦΟΡΙΚΗΣ | W32: ΠΑΡΑΙΤΗΘΗΚΕ | X32: 0 | AA32: 45001 | AB32: ΕΧΕΙ ΠΑΡΑΙΤΗΘΕΙ | AC32: 12441 | AD32: 1382
A33: =--SUBTOTAL(3,$B$2:B32) -> 30 | B33: 1345 | C33: ΚΕ-Γ | D33: 102917 | E33: ΤΣΟΥΜΗΣ | F33: ΙΩΑΝΝΗΣ | G33: ΠΑΝΑΓΙΩΤΗΣ | H33: =TRIM($E33)&" "&TRIM($F33) -> ΤΣΟΥΜΗΣ ΙΩΑΝΝΗΣ | I33: =TRIM($H33)&" - "&TRIM($O33)&" ("&TRIM(C33)&")" -> ΤΣΟΥΜΗΣ ΙΩΑΝΝΗΣ - ΤΕ ΗΛ. ΜΗΧ. (ΚΕ-Γ) | J33: 031000868 | K33: 07:00 - 15:00 | L33: 213 1523731 | M33: 2106543664 | N33: 6972309803 | O33: ΤΕ ΗΛ. ΜΗΧ. | P33: Μ | Q33: Μηχανικός | R33: ΙΔΑΧ | S33: itsoumis@civilprotection.gr | T33: _ | U33: ΔΑΕΦΚ ΚΕ-Δ26 (ΤΜΗΜΑ ΔΙΑΧΕΙΡΙΣΗΣ ΠΡΟΣΩΡΙΝΗΣ ΣΤΕΓΑΣΗΣ ΚΑΙ ΕΞΟΠΛΙΣΜΟΥ) | W33: ΔΑΕΦΚ-ΚΕ ΤΜΗΜΑ Γ | X33: 17 | AA33: 45479 | AB33: ΣΥΝΤΑΞΗ | AC33: 14410 | AD33: 1385
A34: =--SUBTOTAL(3,$B$2:B33) -> 31 | B34: 1161 | C34: ΆΛΛΟ | D34: 12284 | E34: ΧΑΡΑΛΑΜΠΟΠΟΥΛΟΥ | F34: ΧΡΥΣΑΝΘΗ | G34: ΑΝΔΡΕΑΣ | H34: =TRIM($E34)&" "&TRIM($F34) -> ΧΑΡΑΛΑΜΠΟΠΟΥΛΟΥ ΧΡΥΣΑΝΘΗ | I34: =TRIM($H34)&" - "&TRIM($O34)&" ("&TRIM(W34)&")" -> ΧΑΡΑΛΑΜΠΟΠΟΥΛΟΥ ΧΡΥΣΑΝΘΗ - ΠΕ ΔΙΟΙΚ.-ΟΙΚ. (ΔΙΑΧΕΙΡΙΣΤΙΚΗ ΑΡΧΗ) | J34: 047562104 | K34: _ | L34: _ | M34: 2106543664 | N34: 2109316112 | O34: ΠΕ ΔΙΟΙΚ.-ΟΙΚ. | P34: =LEFT(Q34,1) -> Δ | Q34: Διοικητικός | R34: ΜΟΝΙΜΟΣ | S34: _ | T34: _ | U34: ΔΑΕΦΚ ΚΕ-Δ26 (ΤΜΗΜΑ ΔΙΑΧΕΙΡΙΣΗΣ ΠΡΟΣΩΡΙΝΗΣ ΣΤΕΓΑΣΗΣ ΚΑΙ ΕΞΟΠΛΙΣΜΟΥ) | V34: ΆΛΛΗ ΔΙΕΥΘΥΝΣΗ | W34: ΔΙΑΧΕΙΡΙΣΤΙΚΗ ΑΡΧΗ | X34: 17 | Y34: 44831 | Z34: 358519/15.11.2022 | AA34: 45562
A35: =--SUBTOTAL(3,$B$2:B34) -> 32 | B35: 1346 | C35: ΆΛΛΟ | D35: 14274 | E35: ΨΑΛΤΗΣ | F35: ΙΩΑΝΝΗΣ | G35: ΑΘΑΝΑΣΙΟΣ | H35: =TRIM($E35)&" "&TRIM($F35) -> ΨΑΛΤΗΣ ΙΩΑΝΝΗΣ | I35: =TRIM($H35)&" - "&TRIM($O35)&" ("&TRIM(W35)&")" -> ΨΑΛΤΗΣ ΙΩΑΝΝΗΣ - ΔΕ ΔΙΟΙΚ.-ΓΡΑΜ. (ΑΠΕΒΙΩΣΕ) | J35: 033694323 | K35: Δ | L35: _ | M35: _ | N35: 6976395480 | O35: ΔΕ ΔΙΟΙΚ.-ΓΡΑΜ. | P35: =LEFT(Q35,1) -> Δ | Q35: Διοικητικός | R35: ΙΔΟΧ | S35: ipsaltis@civilprotection.gr | T35: psaltisjn@yahoo.com | U35: ΓΔΑΕΦΚ | V35: Δ24-ΔΙΕΥΘΥΝΣΗ ΜΗΤΡΩΩΝ | W35: ΑΠΕΒΙΩΣΕ | X35: 2 | AB35: ΕΧΕΙ ΠΑΡΑΙΤΗΘΕΙ ΕΊΝΑΙ ΣΤΗ ΔΙΑΠΙΣΤΩΤΙΚΗ, ΑΛΛΑ ΌΧΙ ΣΤΟ EXCEL ΤΗΣ ΓΔΑΕΦΚ - ΠΡΟΣΛΗΨΗ ΓΙΑ ΤΟ ΤΑΕΦΚ ΖΑΚΥΝΘΟΥ | AC35: 14465 | AD35: 1130
A36: =--SUBTOTAL(3,$B$2:B35) -> 33 | B36: 1194 | C36: ΔΑ | D36: 14218 | E36: ΘΕΛΕΡΙΤΗΣ | F36: ΗΛΙΑΣ | G36: ΒΑΣΙΛΕΙΟΣ | H36: =TRIM($E36)&" "&TRIM($F36) -> ΘΕΛΕΡΙΤΗΣ ΗΛΙΑΣ | I36: =TRIM($H36)&" - "&TRIM($O36)&" ("&TRIM(C36)&")" -> ΘΕΛΕΡΙΤΗΣ ΗΛΙΑΣ - ΠΕ ΠΟΛ. ΜΗΧ. (ΔΑ) | J36: 079698002 | K36: 08:30 - 16:30 | L36: 2296 440080 | M36: _ | N36: 6947937446 | O36: ΠΕ ΠΟΛ. ΜΗΧ. | P36: Μ | Q36: Μηχανικός | R36: ΙΔΟΧ | S36: itheleritis@civilprotection.gr | T36: crm125@yahoo.com | U36: ΤΑΕΦΚ ΔΑ | W36: ΤΑΕΦΚ-ΔΑ | X36: 4 | AA36: 45357 | AB36: ΕΧΕΙ ΠΑΡΑΙΤΗΘΕΙ | AD36: 14218

Sheet ΕΠΙΦΥΛΑΚΗ
B1: Γ.Δ.Α.Ε.Φ.Κ. : ΥΠΑΛΛΗΛΟΙ ΣΕ ΕΠΙΦΥΛΑΚΗ | G1: _ | BK1: =IF(SUMPRODUCT((BK4:BK1004=$G$1)*(SUBTOTAL(103,OFFSET(BK4,ROW(BK4:BK1004)-MIN(ROW(BK4:BK1004)),0))))=0,"",SUMPRODUCT((BK4:BK1004=$G$1)*(SUBTOTAL(103,OFFSET(BK4,ROW(BK4:BK1004)-MIN(ROW(BK4:BK1004)),0))))) | BL1: =IF(SUMPRODUCT((BL4:BL1004=$G$1)*(SUBTOTAL(103,OFFSET(BL4,ROW(BL4:BL1004)-MIN(ROW(BL4:BL1004)),0))))=0,"",SUMPRODUCT((BL4:BL1004=$G$1)*(SUBTOTAL(103,OFFSET(BL4,ROW(BL4:BL1004)-MIN(ROW(BL4:BL1004)),0))))) -> 1001 | BM1: =IF(SUMPRODUCT((BM4:BM1004=$G$1)*(SUBTOTAL(103,OFFSET(BM4,ROW(BM4:BM1004)-MIN(ROW(BM4:BM1004)),0))))=0,"",SUMPRODUCT((BM4:BM1004=$G$1)*(SUBTOTAL(103,OFFSET(BM4,ROW(BM4:BM1004)-MIN(ROW(BM4:BM1004)),0))))) -> 1001 | BN1: =IF(SUMPRODUCT((BN4:BN1004=$G$1)*(SUBTOTAL(103,OFFSET(BN4,ROW(BN4:BN1004)-MIN(ROW(BN4:BN1004)),0))))=0,"",SUMPRODUCT((BN4:BN1004=$G$1)*(SUBTOTAL(103,OFFSET(BN4,ROW(BN4:BN1004)-MIN(ROW(BN4:BN1004)),0))))) | BO1: =IF(SUMPRODUCT((BO4:BO1004=$G$1)*(SUBTOTAL(103,OFFSET(BO4,ROW(BO4:BO1004)-MIN(ROW(BO4:BO1004)),0))))=0,"",SUMPRODUCT((BO4:BO1004=$G$1)*(SUBTOTAL(103,OFFSET(BO4,ROW(BO4:BO1004)-MIN(ROW(BO4:BO1004)),0))))) -> 1001 | BP1: =IF(SUMPRODUCT((BP4:BP1004=$G$1)*(SUBTOTAL(103,OFFSET(BP4,ROW(BP4:BP1004)-MIN(ROW(BP4:BP1004)),0))))=0,"",SUMPRODUCT((BP4:BP1004=$G$1)*(SUBTOTAL(103,OFFSET(BP4,ROW(BP4:BP1004)-MIN(ROW(BP4:BP1004)),0))))) -> 1001 | BQ1: =IF(SUMPRODUCT((BQ4:BQ1004=$G$1)*(SUBTOTAL(103,OFFSET(BQ4,ROW(BQ4:BQ1004)-MIN(ROW(BQ4:BQ1004)),0))))=0,"",SUMPRODUCT((BQ4:BQ1004=$G$1)*(SUBTOTAL(103,OFFSET(BQ4,ROW(BQ4:BQ1004)-MIN(ROW(BQ4:BQ1004)),0))))) | BR1: =IF(SUMPRODUCT((BR4:BR1004=$G$1)*(SUBTOTAL(103,OFFSET(BR4,ROW(BR4:BR1004)-MIN(ROW(BR4:BR1004)),0))))=0,"",SUMPRODUCT((BR4:BR1004=$G$1)*(SUBTOTAL(103,OFFSET(BR4,ROW(BR4:BR1004)-MIN(ROW(BR4:BR1004)),0))))) -> 1001 | ... CU1: =IF(SUMPRODUCT((CU4:CU1004=$G$1)*(SUBTOTAL(103,OFFSET(CU4,ROW(CU4:CU1004)-MIN(ROW(CU4:CU1004)),0))))=0,"",SUMPRODUCT((CU4:CU1004=$G$1)*(SUBTOTAL(103,OFFSET(CU4,ROW(CU4:CU1004)-MIN(ROW(CU4:CU1004)),0)))))
B2: ΗΜΕΡΟΜΗΝΙΑ
A3: α/α | B3: από | C3: έως | D3: ΥΠΗΡΕΣΙΑ | E3: YPHRESIA | F3: YPALLHLOI | G3: SUM | H3: DUP | I3: ΣΥΝΟΛΟ ΥΠΑΛΛΗΛΩΝ | J3: Υπάλληλος 1 | K3: ΤΗΛΕΦΩΝΟ | M3: Υπάλληλος 2 | N3: ΤΗΛΕΦΩΝΟ | P3: Υπάλληλος 3 | Q3: ΤΗΛΕΦΩΝΟ | S3: Υπάλληλος 4 | T3: ΤΗΛΕΦΩΝΟ | V3: Υπάλληλος 5 | W3: ΤΗΛΕΦΩΝΟ | Y3: Υπάλληλος 6 | Z3: ΤΗΛΕΦΩΝΟ | AB3: Υπάλληλος 7 | AC3: ΤΗΛΕΦΩΝΟ | AE3: Υπάλληλος 8 | AF3: ΤΗΛΕΦΩΝΟ | AH3: Υπάλληλος 9 | AI3: ΤΗΛΕΦΩΝΟ | AK3: Υπάλληλος 10 | AL3: ΤΗΛΕΦΩΝΟ | AN3: Υπάλληλος 11 | AO3: ΤΗΛΕΦΩΝΟ | AQ3: Υπάλληλος 12 | AR3: ΤΗΛΕΦΩΝΟ | AT3: Υπάλληλος 13 | AU3: ΤΗΛΕΦΩΝΟ | AW3: Υπάλληλος 14 | AX3: ΤΗΛΕΦΩΝΟ | AZ3: Υπάλληλος 15 | BA3: ΤΗΛΕΦΩΝΟ | BC3: Υπάλληλος 16 | BD3: ΤΗΛΕΦΩΝΟ | BF3: Υπάλληλος 17 | BG3: ΤΗΛΕΦΩΝΟ | BI3: Υπάλληλος 18 | BJ3: ΤΗΛΕΦΩΝΟ | BL3: Υπάλληλος 19 | BM3: ΤΗΛΕΦΩΝΟ | BO3: Υπάλληλος 20 | BP3: ΤΗΛΕΦΩΝΟ | BR3: Υπάλληλος 21 | BU3: Υπάλληλος 22 | BX3: Υπάλληλος 23 | CA3: Υπάλληλος 24 | CD3: Υπάλληλος 25 | CG3: Υπάλληλος 26 | CJ3: Υπάλληλος 27 | CM3: Υπάλληλος 28 | CP3: Υπάλληλος 29 | CS3: Υπάλληλος 30
